Workbook

Sheet Setup_Macro
B1: ⚙️ SETUP MACRO — CONFIGURAZIONE
B3: ⚠ IMPORTANTE: scrivi il percorso del file storico DIRETTAMENTE nella cella D4 (es: C:\Users\Mario\Desktop\Riepilogo_Energia_STORICO.xlsx) e salva il file. Non basta selezionarlo dalla finestra di dialogo — devi digitarlo nella cella.
B4: Percorso file storico: | D4: C:\Users\TuoNome\Desktop\Riepilogo_Energia_STORICO.xlsx
B5: Anno PVGIS (2005-2020): | D5: 2020 | E5: ⚠ Max 2020 — oltre questa data PVGIS non ha dati
B6: Percorso detailed-history.xlsx: | D6: C:\Users\TuoNome\Desktop\detailed-history.xlsx
B7: ISTRUZIONI: 1) Alt+F11 → Inserisci Modulo → incolla codice → Ctrl+S → .xlsm | 2) Crea pulsanti in Dashboard: verde=AggiornaDaStorico | viola=AggiornaPVGIS | blu=AggiornaCompleto
B8: CODICE VBA — copia tutto il testo verde sotto e incollalo nel Modulo VBA
B9: ' D4 = percorso Riepilogo_Energia_STORICO.xlsx
B10: ' D5 = Anno (PVGIS max 2020 | Open-Meteo storico da 1940)
B11: ' D6 = percorso detailed-history.xlsx (incentivi)
B13: Sub TestPVGIS_Debug()
B14: Dim http As Object, sUrl As String, sResp As String
B15: sUrl = "https://re.jrc.ec.europa.eu/api/v5_2/PVcalc"
B16: sUrl = sUrl & "?lat=37.236750&lon=13.742667&peakpower=1&loss=0"
B17: sUrl = sUrl & "&angle=30&aspect=0&startyear=2020&endyear=2020&outputformat=json"
B18: Set http = CreateObject("WinHttp.WinHttpRequest.5.1")
B19: http.Open "GET", sUrl, False
... B407: End Function

Sheet Fonte_Dati
B1: 📥 FONTE DATI — STORICO ENERGIA & FATTURATO
B4: Importato da: Riepilogo_Energia_STORICO.xlsx | Periodo: Q1 2026 | 16 Impianti | Aggiornato: 16/03/2026
B5: ⚠ Questo foglio è la fonte centralizzata. Gli altri fogli leggono da qui via SUMIF. Non modificare la struttura.
B7: Anno | C7: Mese | D7: Impianto | E7: Energia Mis. (kWh) | F7: Energia Magg. (kWh) | G7: Fatturato Lordo (€) | H7: Fee (€) | I7: Fatturato Netto (€) | J7: EUR/MWh | K7: Tipo
B8: 2026 | C8: Gennaio | D8: FV-Batia S. Francesco | E8: 425760.24 | F8: 424057.2 | G8: 47434.025 | H8: -84.81144 | I8: 47349.213 | J8: 0 | K8: Fotovoltaico
B9: 2026 | C9: Gennaio | D9: FV-Campofranco Tetto | E9: 24295.24 | F9: 24854.031 | G9: 3025.1312 | H9: -4.9708061 | I9: 3020.1604 | J9: 0 | K9: Fotovoltaico
B10: 2026 | C10: Gennaio | D10: FV-Fauma Tetto | E10: 652486.4 | F10: 667493.59 | G10: 79168.413 | H10: -133.49872 | I10: 79034.914 | J10: 0 | K10: Fotovoltaico
B11: 2026 | C11: Gennaio | D11: FV-Favara Grande | E11: 629425.76 | F11: 643902.55 | G11: 76759.684 | H11: -128.78051 | I11: 76630.904 | J11: 0 | K11: Fotovoltaico
B12: 2026 | C12: Gennaio | D12: FV-Malvizzo Piccolo | E12: 111376.12 | F12: 110930.62 | G12: 12280.38 | H12: -22.186124 | I12: 12258.194 | J12: 0 | K12: Fotovoltaico
B13: 2026 | C13: Gennaio | D13: FV-Malvizzo a Terra | E13: 112069.2 | F13: 111620.92 | G13: 12199.659 | H13: -22.324185 | I13: 12177.335 | J13: 0 | K13: Fotovoltaico
B14: 2026 | C14: Gennaio | D14: FV-Narbone Piccolo | E14: 33209.7 | F14: 33076.861 | G14: 3870.2981 | H14: -6.6153722 | I14: 3863.6828 | J14: 0 | K14: Fotovoltaico
B15: 2026 | C15: Gennaio | D15: FV-Narbone a Terra Grande | E15: 76190.16 | F15: 75885.399 | G15: 8742.4718 | H15: -15.17708 | I15: 8727.2947 | J15: 0 | K15: Fotovoltaico
B16: 2026 | C16: Gennaio | D16: FV-Perniciara | E16: 209754.75 | F16: 214579.11 | G16: 25631.128 | H16: -42.915822 | I16: 25588.212 | J16: 0 | K16: Fotovoltaico
B17: 2026 | C17: Gennaio | D17: FV-Serre Gela | E17: 199294.56 | F17: 203878.33 | G17: 24021.424 | H17: -40.775667 | I17: 23980.648 | J17: 0 | K17: Fotovoltaico
B18: 2026 | C18: Gennaio | D18: FV-Serre Narbone | E18: 353361.6 | F18: 351948.15 | G18: 41581.31 | H18: -70.389631 | I18: 41510.92 | J18: 0 | K18: Fotovoltaico
B19: 2026 | C19: Gennaio | D19: FV-Serre S.Angelo Muxaro | E19: 356199.6 | F19: 364392.19 | G19: 43280.191 | H19: -72.878438 | I19: 43207.313 | J19: 0 | K19: Fotovoltaico
... B55: 2026 | C55: Marzo | D55: Wind - Monte Narbone | E55: 348.54082 | F55: 356.55726 | G55: 43.314576 | H55: -0.071311452 | I55: 43.243264 | J55: 0 | K55: Eolico
B56: TOTALE Q1 2026 | E56: =SUM(F8:F55) -> 28924178 | F56: =SUM(G8:G55) -> 3133013.1 | G56: =SUM(H8:H55) -> -5784.8357 | H56: =SUM(I8:I55) -> 3127228.3 | I56: =SUM(J8:J55) -> 0

Sheet DB_Impianti
B1: 🗄️ DATABASE PORTFOLIO — DATI REALI Q1 2026
B4: 16 Impianti (13 FV + 3 Eolici) | Q1 2026 | Celle gialle = dati tecnici da completare
B6: ANAGRAFICA IMPIANTI | K6: DATI TECNICI (da compilare) | U6: PR — Formula IEC 61724-1
B7: ID | C7: Impianto | D7: Tipo | E7: Trader | F7: Ragione Sociale | G7: PVI | H7: Fee (€/MWh) | I7: Regione | J7: Anno Ins. | K7: kWp DC ⚠ | L7: kW AC ⚠ | M7: Vita Resid.⚠ | N7: En. Mis. Q1 (MWh) | O7: En. Magg. Q1 (MWh) | P7: Fatturato Lordo Q1 (€) | Q7: Fee Q1 (€) | R7: Fatturato Netto Q1 (€) | S7: EUR/MWh medio | T7: OPEX est. (€) | U7: Irr. Q1 (kWh/m²) | V7: PR Q1 (%) IEC
B8: 1 | C8: Wind - Monte Narbone | D8: Eolico | E8: DXT | F8: Moncada Energy Group Srl | G8: PVI_S19MNEN_001 | H8: -1.36 | I8: Sicilia | N8: =IFERROR(SUMIFS(Fonte_Dati!E:E,Fonte_Dati!D:D,C8)/1000,0) -> 9096.2236 | O8: =IFERROR(SUMIFS(Fonte_Dati!F:F,Fonte_Dati!D:D,C8)/1000,0) -> 9096.2316 | P8: =IFERROR(SUMIFS(Fonte_Dati!G:G,Fonte_Dati!D:D,C8),0) -> 1042617.3 | Q8: =IFERROR(SUMIFS(Fonte_Dati!H:H,Fonte_Dati!D:D,C8),0) -> -1819.2463 | R8: =IFERROR(SUMIFS(Fonte_Dati!I:I,Fonte_Dati!D:D,C8),0) -> 1040798.1 | S8: =IFERROR(R8/O8,0) -> 114.4208 | T8: =IFERROR(R8*0.08,0) -> 83263.847 | U8: =IFERROR(VLOOKUP(C8,Irraggiamento_PVGIS!C50:H65,6,0),"") | V8: =IFERROR((N8*1000)/(U8*K8),"")
B9: 2 | C9: Wind - Monte Durrà | D9: Eolico | E9: BANCO ENERGIA | F9: Moncada Energy Group Srl | G9: PVI_S19MDEN_001 | H9: -1.86 | I9: Sicilia | N9: =IFERROR(SUMIFS(Fonte_Dati!E:E,Fonte_Dati!D:D,C9)/1000,0) -> 8107.3148 | O9: =IFERROR(SUMIFS(Fonte_Dati!F:F,Fonte_Dati!D:D,C9)/1000,0) -> 8107.3148 | P9: =IFERROR(SUMIFS(Fonte_Dati!G:G,Fonte_Dati!D:D,C9),0) -> 908432.26 | Q9: =IFERROR(SUMIFS(Fonte_Dati!H:H,Fonte_Dati!D:D,C9),0) -> -1621.463 | R9: =IFERROR(SUMIFS(Fonte_Dati!I:I,Fonte_Dati!D:D,C9),0) -> 906810.8 | S9: =IFERROR(R9/O9,0) -> 111.85094 | T9: =IFERROR(R9*0.08,0) -> 72544.864 | U9: =IFERROR(VLOOKUP(C9,Irraggiamento_PVGIS!C50:H65,6,0),"") | V9: =IFERROR((N9*1000)/(U9*K9),"")
B10: 3 | C10: Wind - Monte Malvizzo | D10: Eolico | E10: DXT | F10: Moncada Energy Group Srl | G10: PVI_S19MMEN_001 | H10: -1.36 | I10: Sicilia | N10: =IFERROR(SUMIFS(Fonte_Dati!E:E,Fonte_Dati!D:D,C10)/1000,0) -> 3945.0563 | O10: =IFERROR(SUMIFS(Fonte_Dati!F:F,Fonte_Dati!D:D,C10)/1000,0) -> 3945.0775 | P10: =IFERROR(SUMIFS(Fonte_Dati!G:G,Fonte_Dati!D:D,C10),0) -> 445055.51 | Q10: =IFERROR(SUMIFS(Fonte_Dati!H:H,Fonte_Dati!D:D,C10),0) -> -789.0155 | R10: =IFERROR(SUMIFS(Fonte_Dati!I:I,Fonte_Dati!D:D,C10),0) -> 444266.5 | S10: =IFERROR(R10/O10,0) -> 112.61287 | T10: =IFERROR(R10*0.08,0) -> 35541.32 | U10: =IFERROR(VLOOKUP(C10,Irraggiamento_PVGIS!C50:H65,6,0),"") | V10: =IFERROR((N10*1000)/(U10*K10),"")
B11: 4 | C11: FV-Favara Grande | D11: Fotovoltaico | E11: AXPO | F11: Biopower 2 Srl | H11: -0.2 | I11: Sicilia | N11: =IFERROR(SUMIFS(Fonte_Dati!E:E,Fonte_Dati!D:D,C11)/1000,0) -> 1544.2125 | O11: =IFERROR(SUMIFS(Fonte_Dati!F:F,Fonte_Dati!D:D,C11)/1000,0) -> 1579.7294 | P11: =IFERROR(SUMIFS(Fonte_Dati!G:G,Fonte_Dati!D:D,C11),0) -> 150406.67 | Q11: =IFERROR(SUMIFS(Fonte_Dati!H:H,Fonte_Dati!D:D,C11),0) -> -315.94587 | R11: =IFERROR(SUMIFS(Fonte_Dati!I:I,Fonte_Dati!D:D,C11),0) -> 150090.73 | S11: =IFERROR(R11/O11,0) -> 95.010406 | T11: =IFERROR(R11*0.08,0) -> 12007.258 | U11: =IFERROR(VLOOKUP(C11,Irraggiamento_PVGIS!C50:H65,6,0),"") -> 0 | V11: =IFERROR((N11*1000)/(U11*K11),"")
B12: 5 | C12: FV-Fauma Tetto | D12: Fotovoltaico | E12: AXPO | F12: Biopower 3 Srl | H12: -0.2 | I12: Sicilia | N12: =IFERROR(SUMIFS(Fonte_Dati!E:E,Fonte_Dati!D:D,C12)/1000,0) -> 1503.9636 | O12: =IFERROR(SUMIFS(Fonte_Dati!F:F,Fonte_Dati!D:D,C12)/1000,0) -> 1538.5548 | P12: =IFERROR(SUMIFS(Fonte_Dati!G:G,Fonte_Dati!D:D,C12),0) -> 148356.71 | Q12: =IFERROR(SUMIFS(Fonte_Dati!H:H,Fonte_Dati!D:D,C12),0) -> -307.71095 | R12: =IFERROR(SUMIFS(Fonte_Dati!I:I,Fonte_Dati!D:D,C12),0) -> 148049 | S12: =IFERROR(R12/O12,0) -> 96.226018 | T12: =IFERROR(R12*0.08,0) -> 11843.92 | U12: =IFERROR(VLOOKUP(C12,Irraggiamento_PVGIS!C50:H65,6,0),"") -> 0 | V12: =IFERROR((N12*1000)/(U12*K12),"")
B13: 6 | C13: FV-Batia S. Francesco | D13: Fotovoltaico | E13: DXT | F13: Energie Innovative Srl | G13: PVI_0435789_001 | H13: -0.2 | I13: Sicilia | N13: =IFERROR(SUMIFS(Fonte_Dati!E:E,Fonte_Dati!D:D,C13)/1000,0) -> 1146.8885 | O13: =IFERROR(SUMIFS(Fonte_Dati!F:F,Fonte_Dati!D:D,C13)/1000,0) -> 1142.3009 | P13: =IFERROR(SUMIFS(Fonte_Dati!G:G,Fonte_Dati!D:D,C13),0) -> 103510.6 | Q13: =IFERROR(SUMIFS(Fonte_Dati!H:H,Fonte_Dati!D:D,C13),0) -> -228.46019 | R13: =IFERROR(SUMIFS(Fonte_Dati!I:I,Fonte_Dati!D:D,C13),0) -> 103282.14 | S13: =IFERROR(R13/O13,0) -> 90.415876 | T13: =IFERROR(R13*0.08,0) -> 8262.5711 | U13: =IFERROR(VLOOKUP(C13,Irraggiamento_PVGIS!C50:H65,6,0),"") -> 0 | V13: =IFERROR((N13*1000)/(U13*K13),"")
B14: 7 | C14: FV-Serre S.Angelo Muxaro | D14: Fotovoltaico | E14: DXT | F14: Società Agricola Solar Farm 3 Srl | G14: PVI_0363736_001 | H14: -0.2 | I14: Sicilia | N14: =IFERROR(SUMIFS(Fonte_Dati!E:E,Fonte_Dati!D:D,C14)/1000,0) -> 787.1292 | O14: =IFERROR(SUMIFS(Fonte_Dati!F:F,Fonte_Dati!D:D,C14)/1000,0) -> 805.23317 | P14: =IFERROR(SUMIFS(Fonte_Dati!G:G,Fonte_Dati!D:D,C14),0) -> 77680.731 | Q14: =IFERROR(SUMIFS(Fonte_Dati!H:H,Fonte_Dati!D:D,C14),0) -> -161.04663 | R14: =IFERROR(SUMIFS(Fonte_Dati!I:I,Fonte_Dati!D:D,C14),0) -> 77519.685 | S14: =IFERROR(R14/O14,0) -> 96.26986 | T14: =IFERROR(R14*0.08,0) -> 6201.5748 | U14: =IFERROR(VLOOKUP(C14,Irraggiamento_PVGIS!C50:H65,6,0),"") -> 0 | V14: =IFERROR((N14*1000)/(U14*K14),"")
B15: 8 | C15: FV-Serre Narbone | D15: Fotovoltaico | E15: DXT | F15: Società Agricola Solar Farm Srl | G15: PVI_S19SNRR_001 | H15: -0.2 | I15: Sicilia | N15: =IFERROR(SUMIFS(Fonte_Dati!E:E,Fonte_Dati!D:D,C15)/1000,0) -> 801.5076 | O15: =IFERROR(SUMIFS(Fonte_Dati!F:F,Fonte_Dati!D:D,C15)/1000,0) -> 798.30157 | P15: =IFERROR(SUMIFS(Fonte_Dati!G:G,Fonte_Dati!D:D,C15),0) -> 76124.436 | Q15: =IFERROR(SUMIFS(Fonte_Dati!H:H,Fonte_Dati!D:D,C15),0) -> -159.66031 | R15: =IFERROR(SUMIFS(Fonte_Dati!I:I,Fonte_Dati!D:D,C15),0) -> 75964.775 | S15: =IFERROR(R15/O15,0) -> 95.157993 | T15: =IFERROR(R15*0.08,0) -> 6077.182 | U15: =IFERROR(VLOOKUP(C15,Irraggiamento_PVGIS!C50:H65,6,0),"") -> 0 | V15: =IFERROR((N15*1000)/(U15*K15),"")
B16: 9 | C16: FV-Perniciara | D16: Fotovoltaico | E16: AXPO | F16: Biopower 2 Srl | H16: -0.2 | I16: Sicilia | N16: =IFERROR(SUMIFS(Fonte_Dati!E:E,Fonte_Dati!D:D,C16)/1000,0) -> 521.4165 | O16: =IFERROR(SUMIFS(Fonte_Dati!F:F,Fonte_Dati!D:D,C16)/1000,0) -> 533.40908 | P16: =IFERROR(SUMIFS(Fonte_Dati!G:G,Fonte_Dati!D:D,C16),0) -> 50858.787 | Q16: =IFERROR(SUMIFS(Fonte_Dati!H:H,Fonte_Dati!D:D,C16),0) -> -106.68182 | R16: =IFERROR(SUMIFS(Fonte_Dati!I:I,Fonte_Dati!D:D,C16),0) -> 50752.105 | S16: =IFERROR(R16/O16,0) -> 95.146684 | T16: =IFERROR(R16*0.08,0) -> 4060.1684 | U16: =IFERROR(VLOOKUP(C16,Irraggiamento_PVGIS!C50:H65,6,0),"") -> 0 | V16: =IFERROR((N16*1000)/(U16*K16),"")
B17: 10 | C17: FV-Serre Gela | D17: Fotovoltaico | E17: DXT | F17: Società Agricola Solar Farm 5 Srl | G17: PVI_0384558_001 | H17: -0.2 | I17: Sicilia | N17: =IFERROR(SUMIFS(Fonte_Dati!E:E,Fonte_Dati!D:D,C17)/1000,0) -> 476.96608 | O17: =IFERROR(SUMIFS(Fonte_Dati!F:F,Fonte_Dati!D:D,C17)/1000,0) -> 487.9363 | P17: =IFERROR(SUMIFS(Fonte_Dati!G:G,Fonte_Dati!D:D,C17),0) -> 46577.793 | Q17: =IFERROR(SUMIFS(Fonte_Dati!H:H,Fonte_Dati!D:D,C17),0) -> -97.58726 | R17: =IFERROR(SUMIFS(Fonte_Dati!I:I,Fonte_Dati!D:D,C17),0) -> 46480.205 | S17: =IFERROR(R17/O17,0) -> 95.258757 | T17: =IFERROR(R17*0.08,0) -> 3718.4164 | U17: =IFERROR(VLOOKUP(C17,Irraggiamento_PVGIS!C50:H65,6,0),"") -> 0 | V17: =IFERROR((N17*1000)/(U17*K17),"")
B18: 11 | C18: FV-Malvizzo Piccolo | D18: Fotovoltaico | E18: AXPO | F18: ERM Srl | H18: -0.2 | I18: Sicilia | N18: =IFERROR(SUMIFS(Fonte_Dati!E:E,Fonte_Dati!D:D,C18)/1000,0) -> 326.17582 | O18: =IFERROR(SUMIFS(Fonte_Dati!F:F,Fonte_Dati!D:D,C18)/1000,0) -> 324.87112 | P18: =IFERROR(SUMIFS(Fonte_Dati!G:G,Fonte_Dati!D:D,C18),0) -> 29734.277 | Q18: =IFERROR(SUMIFS(Fonte_Dati!H:H,Fonte_Dati!D:D,C18),0) -> -64.974224 | R18: =IFERROR(SUMIFS(Fonte_Dati!I:I,Fonte_Dati!D:D,C18),0) -> 29669.302 | S18: =IFERROR(R18/O18,0) -> 91.326377 | T18: =IFERROR(R18*0.08,0) -> 2373.5442 | U18: =IFERROR(VLOOKUP(C18,Irraggiamento_PVGIS!C50:H65,6,0),"") -> 0 | V18: =IFERROR((N18*1000)/(U18*K18),"")
B19: 12 | C19: FV-Malvizzo a Terra | D19: Fotovoltaico | E19: DXT | F19: Moncada Energy Solar Srl | G19: PVI_0397946_001 | H19: -0.2 | I19: Sicilia | N19: =IFERROR(SUMIFS(Fonte_Dati!E:E,Fonte_Dati!D:D,C19)/1000,0) -> 320.47704 | O19: =IFERROR(SUMIFS(Fonte_Dati!F:F,Fonte_Dati!D:D,C19)/1000,0) -> 319.19513 | P19: =IFERROR(SUMIFS(Fonte_Dati!G:G,Fonte_Dati!D:D,C19),0) -> 29047.258 | Q19: =IFERROR(SUMIFS(Fonte_Dati!H:H,Fonte_Dati!D:D,C19),0) -> -63.839026 | R19: =IFERROR(SUMIFS(Fonte_Dati!I:I,Fonte_Dati!D:D,C19),0) -> 28983.419 | S19: =IFERROR(R19/O19,0) -> 90.80157 | T19: =IFERROR(R19*0.08,0) -> 2318.6735 | U19: =IFERROR(VLOOKUP(C19,Irraggiamento_PVGIS!C50:H65,6,0),"") -> 0 | V19: =IFERROR((N19*1000)/(U19*K19),"")
B20: 13 | C20: FV-Narbone a Terra Grande | D20: Fotovoltaico | E20: DXT | F20: Moncada Energy Solar Srl | G20: PVI_0397937_001 | H20: -0.2 | I20: Sicilia | N20: =IFERROR(SUMIFS(Fonte_Dati!E:E,Fonte_Dati!D:D,C20)/1000,0) -> 76.19016 | O20: =IFERROR(SUMIFS(Fonte_Dati!F:F,Fonte_Dati!D:D,C20)/1000,0) -> 75.885399 | P20: =IFERROR(SUMIFS(Fonte_Dati!G:G,Fonte_Dati!D:D,C20),0) -> 8742.4718 | Q20: =IFERROR(SUMIFS(Fonte_Dati!H:H,Fonte_Dati!D:D,C20),0) -> -15.17708 | R20: =IFERROR(SUMIFS(Fonte_Dati!I:I,Fonte_Dati!D:D,C20),0) -> 8727.2947 | S20: =IFERROR(R20/O20,0) -> 115.00624 | T20: =IFERROR(R20*0.08,0) -> 698.18358 | U20: =IFERROR(VLOOKUP(C20,Irraggiamento_PVGIS!C50:H65,6,0),"") -> 0 | V20: =IFERROR((N20*1000)/(U20*K20),"")
B21: 14 | C21: FV-Narbone Piccolo | D21: Fotovoltaico | E21: AXPO | F21: ERM Srl | H21: -0.2 | I21: Sicilia | N21: =IFERROR(SUMIFS(Fonte_Dati!E:E,Fonte_Dati!D:D,C21)/1000,0) -> 78.51654 | O21: =IFERROR(SUMIFS(Fonte_Dati!F:F,Fonte_Dati!D:D,C21)/1000,0) -> 78.202474 | P21: =IFERROR(SUMIFS(Fonte_Dati!G:G,Fonte_Dati!D:D,C21),0) -> 7402.499 | Q21: =IFERROR(SUMIFS(Fonte_Dati!H:H,Fonte_Dati!D:D,C21),0) -> -15.640495 | R21: =IFERROR(SUMIFS(Fonte_Dati!I:I,Fonte_Dati!D:D,C21),0) -> 7386.8585 | S21: =IFERROR(R21/O21,0) -> 94.458118 | T21: =IFERROR(R21*0.08,0) -> 590.94868 | U21: =IFERROR(VLOOKUP(C21,Irraggiamento_PVGIS!C50:H65,6,0),"") -> 0 | V21: =IFERROR((N21*1000)/(U21*K21),"")
B22: 15 | C22: FV-Campofranco Tetto | D22: Fotovoltaico | E22: DXT | F22: Moncada Energy Group Srl | G22: PVI_0130620_001 | H22: -0.2 | I22: Sicilia | N22: =IFERROR(SUMIFS(Fonte_Dati!E:E,Fonte_Dati!D:D,C22)/1000,0) -> 70.70192 | O22: =IFERROR(SUMIFS(Fonte_Dati!F:F,Fonte_Dati!D:D,C22)/1000,0) -> 72.328064 | P22: =IFERROR(SUMIFS(Fonte_Dati!G:G,Fonte_Dati!D:D,C22),0) -> 6636.8041 | Q22: =IFERROR(SUMIFS(Fonte_Dati!H:H,Fonte_Dati!D:D,C22),0) -> -14.465613 | R22: =IFERROR(SUMIFS(Fonte_Dati!I:I,Fonte_Dati!D:D,C22),0) -> 6622.3385 | S22: =IFERROR(R22/O22,0) -> 91.559736 | T22: =IFERROR(R22*0.08,0) -> 529.78708 | U22: =IFERROR(VLOOKUP(C22,Irraggiamento_PVGIS!C50:H65,6,0),"") -> 0 | V22: =IFERROR((N22*1000)/(U22*K22),"")
B23: 16 | C23: FV-Tumarrano MEG | D23: Fotovoltaico | E23: DXT | F23: Moncada Energy Group Srl | G23: PVI_0558896_001 | H23: -0.2 | I23: Sicilia | N23: =IFERROR(SUMIFS(Fonte_Dati!E:E,Fonte_Dati!D:D,C23)/1000,0) -> 19.16622 | O23: =IFERROR(SUMIFS(Fonte_Dati!F:F,Fonte_Dati!D:D,C23)/1000,0) -> 19.607043 | P23: =IFERROR(SUMIFS(Fonte_Dati!G:G,Fonte_Dati!D:D,C23),0) -> 1828.9881 | Q23: =IFERROR(SUMIFS(Fonte_Dati!H:H,Fonte_Dati!D:D,C23),0) -> -3.9214086 | R23: =IFERROR(SUMIFS(Fonte_Dati!I:I,Fonte_Dati!D:D,C23),0) -> 1825.0667 | S23: =IFERROR(R23/O23,0) -> 93.082199 | T23: =IFERROR(R23*0.08,0) -> 146.00533 | U23: =IFERROR(VLOOKUP(C23,Irraggiamento_PVGIS!C50:H65,6,0),"") -> 0 | V23: =IFERROR((N23*1000)/(U23*K23),"")
B24: TOTALE PORTFOLIO Q1 2026 | N24: =SUM(O8:O23) -> 28924.178 | O24: =SUM(P8:P23) -> 3133013.1 | P24: =SUM(Q8:Q23) -> -5784.8357 | Q24: =SUM(R8:R23) -> 3127228.3 | R24: =IFERROR(SUM(R8:R23),0) -> 3127228.3 | S24: =IFERROR(R24/O24,"") -> 0.99815359 | T24: =IFERROR(SUM(T8:T23),0) -> 250178.26 | U24: =IFERROR(AVERAGE(V8:V23),"") | V24: =IFERROR(AVERAGE(V8:V23),"")

Sheet Dashboard
B1: ☀ PORTFOLIO AM — DASHBOARD ESECUTIVO ☀
B4: Q1 2026 | 16 Impianti (13 FV + 3 Eolici) | Elaborato: 16/03/2026
B5: ▶ AGGIORNA DATI | E5: 🌞 AGGIORNA PVGIS | I5: ▶▶ AGGIORNA TUTTO (storico + PVGIS) | L5: ← Assegna macro: verde=AggiornaDaStorico | viola=AggiornaPVGIS | blu=AggiornaCompleto
C6: ⚡ ENERGIA MISURATA Q1 | F6: 💰 FATTURATO NETTO Q1 | I6: 📈 PREZZO MEDIO EUR/MWh | L6: 🔋 IMPIANTI ATTIVI
C7: 28,822 MWh | F7: € 3.127 M | I7: € 108.12/MWh | L7: 16 / 16
C8: ▲ Gennaio + Febbraio + Marzo | F8: ▲ Fee contrattuale applicata | I8: ▲ Media ponderata per MWh | L8: ✅ Portfolio 100% operativo
C10: ☀ IMPIANTI FOTOVOLTAICI | F10: 💨 IMPIANTI EOLICI | I10: 💹 FATTURATO LORDO Q1 | L10: 🏦 EBITDA STIMATO Q1
C11: 13 impianti | F11: 3 impianti | I11: € 3.133 M | L11: € 2.877 M
C12: Fat. Netto: € 0.735 M | F12: Fat. Netto: € 2.392 M | I12: Fee totale: € 5,785 | L12: ▲ Margin ~92% (OPEX ~8%)
B13: 💹 INCENTIVI GSE — ACCONTO Q1 2026 (ADVANCE-GSE × TARIFF)
C14: 💹 ACCONTO INCENTIVI Q1 | F14: ✅ CONSUNTIVO INCENTIVI Q1 | I14: 📐 DELTA Cons. − Acc. | L14: 🏦 EBITDA + INCENTIVI
C15: =IFERROR(TEXT('💹 Incentivi'!R24,"€ #,##0"),"—") -> € 2,826,099 | F15: =IFERROR(TEXT('💹 Incentivi'!R44,"€ #,##0"),"—") -> € 1,123,198 | I15: =IFERROR(TEXT('💹 Incentivi'!R64,"+€ #,##0;-€ #,##0;€ 0"),"—") -> -€ 1,702,901 | L15: =IFERROR(TEXT(Finanziario!N24,"€ #,##0"),"—") -> € 4,582,009
C16: ADVANCE-GSE × Tariffa | F16: OWNER × Tariffa | I16: Aggiustamento consuntivo | L16: EBITDA mercato + cons. inc.
C17: RIEPILOGO IMPIANTI — STATUS Q1 2026
C18: ID | D18: Impianto | E18: Tipo | F18: Trader | G18: Ragione Sociale | H18: En. Mis. Q1 (MWh) | I18: En. Magg. Q1 (MWh) | J18: Fat. Lordo (€) | K18: Fee (€) | L18: Fat. Netto (€) | M18: EUR/MWh | N18: OPEX est. (€)
C19: 1 | D19: Wind - Monte Narbone | E19: Eolico | F19: =IFERROR(SUMIFS(Fonte_Dati!E:E,Fonte_Dati!D:D,D16)/1000,0) -> 0 | G19: =IFERROR(SUMIFS(Fonte_Dati!F:F,Fonte_Dati!D:D,D16)/1000,0) -> 0 | H19: =IFERROR(SUMIFS(Fonte_Dati!G:G,Fonte_Dati!D:D,D16),0) -> 0 | I19: =IFERROR(SUMIFS(Fonte_Dati!H:H,Fonte_Dati!D:D,D16),0) -> 0 | J19: =IFERROR(SUMIFS(Fonte_Dati!I:I,Fonte_Dati!D:D,D16),0) -> 0 | K19: =IFERROR(J16/G16,0) -> 0 | L19: =IFERROR(J16*0.08,0) -> 0 | M19: 114.4208 | N19: 83264
C20: 2 | D20: Wind - Monte Durrà | E20: Eolico | F20: =IFERROR(SUMIFS(Fonte_Dati!E:E,Fonte_Dati!D:D,D17)/1000,0) -> 0 | G20: =IFERROR(SUMIFS(Fonte_Dati!F:F,Fonte_Dati!D:D,D17)/1000,0) -> 0 | H20: =IFERROR(SUMIFS(Fonte_Dati!G:G,Fonte_Dati!D:D,D17),0) -> 0 | I20: =IFERROR(SUMIFS(Fonte_Dati!H:H,Fonte_Dati!D:D,D17),0) -> 0 | J20: =IFERROR(SUMIFS(Fonte_Dati!I:I,Fonte_Dati!D:D,D17),0) -> 0 | K20: =IFERROR(J17/G17,0) -> 0 | L20: =IFERROR(J17*0.08,0) -> 0 | M20: 111.85094 | N20: 72545
C21: 3 | D21: Wind - Monte Malvizzo | E21: Eolico | F21: =IFERROR(SUMIFS(Fonte_Dati!E:E,Fonte_Dati!D:D,D18)/1000,0) -> 0 | G21: =IFERROR(SUMIFS(Fonte_Dati!F:F,Fonte_Dati!D:D,D18)/1000,0) -> 0 | H21: =IFERROR(SUMIFS(Fonte_Dati!G:G,Fonte_Dati!D:D,D18),0) -> 0 | I21: =IFERROR(SUMIFS(Fonte_Dati!H:H,Fonte_Dati!D:D,D18),0) -> 0 | J21: =IFERROR(SUMIFS(Fonte_Dati!I:I,Fonte_Dati!D:D,D18),0) -> 0 | K21: =IFERROR(J18/G18,0) -> 0 | L21: =IFERROR(J18*0.08,0) -> 0 | M21: 112.61287 | N21: 35541
C22: 4 | D22: FV-Favara Grande | E22: Fotovoltaico | F22: =IFERROR(SUMIFS(Fonte_Dati!E:E,Fonte_Dati!D:D,D19)/1000,0) -> 9096.2236 | G22: =IFERROR(SUMIFS(Fonte_Dati!F:F,Fonte_Dati!D:D,D19)/1000,0) -> 9096.2316 | H22: =IFERROR(SUMIFS(Fonte_Dati!G:G,Fonte_Dati!D:D,D19),0) -> 1042617.3 | I22: =IFERROR(SUMIFS(Fonte_Dati!H:H,Fonte_Dati!D:D,D19),0) -> -1819.2463 | J22: =IFERROR(SUMIFS(Fonte_Dati!I:I,Fonte_Dati!D:D,D19),0) -> 1040798.1 | K22: =IFERROR(J19/G19,0) -> 0 | L22: =IFERROR(J19*0.08,0) -> 0 | M22: 95.010406 | N22: 12007
C23: 5 | D23: FV-Fauma Tetto | E23: Fotovoltaico | F23: =IFERROR(SUMIFS(Fonte_Dati!E:E,Fonte_Dati!D:D,D20)/1000,0) -> 8107.3148 | G23: =IFERROR(SUMIFS(Fonte_Dati!F:F,Fonte_Dati!D:D,D20)/1000,0) -> 8107.3148 | H23: =IFERROR(SUMIFS(Fonte_Dati!G:G,Fonte_Dati!D:D,D20),0) -> 908432.26 | I23: =IFERROR(SUMIFS(Fonte_Dati!H:H,Fonte_Dati!D:D,D20),0) -> -1621.463 | J23: =IFERROR(SUMIFS(Fonte_Dati!I:I,Fonte_Dati!D:D,D20),0) -> 906810.8 | K23: =IFERROR(J20/G20,0) -> 0 | L23: =IFERROR(J20*0.08,0) -> 0 | M23: 96.226018 | N23: 11844
C24: 6 | D24: FV-Batia S. Francesco | E24: Fotovoltaico | F24: =IFERROR(SUMIFS(Fonte_Dati!E:E,Fonte_Dati!D:D,D21)/1000,0) -> 3945.0563 | G24: =IFERROR(SUMIFS(Fonte_Dati!F:F,Fonte_Dati!D:D,D21)/1000,0) -> 3945.0775 | H24: =IFERROR(SUMIFS(Fonte_Dati!G:G,Fonte_Dati!D:D,D21),0) -> 445055.51 | I24: =IFERROR(SUMIFS(Fonte_Dati!H:H,Fonte_Dati!D:D,D21),0) -> -789.0155 | J24: =IFERROR(SUMIFS(Fonte_Dati!I:I,Fonte_Dati!D:D,D21),0) -> 444266.5 | K24: =IFERROR(J21/G21,0) -> 0 | L24: =IFERROR(J21*0.08,0) -> 0 | M24: 90.415876 | N24: 8263
C25: 7 | D25: FV-Serre S.Angelo Muxaro | E25: Fotovoltaico | F25: =IFERROR(SUMIFS(Fonte_Dati!E:E,Fonte_Dati!D:D,D22)/1000,0) -> 1544.2125 | G25: =IFERROR(SUMIFS(Fonte_Dati!F:F,Fonte_Dati!D:D,D22)/1000,0) -> 1579.7294 | H25: =IFERROR(SUMIFS(Fonte_Dati!G:G,Fonte_Dati!D:D,D22),0) -> 150406.67 | I25: =IFERROR(SUMIFS(Fonte_Dati!H:H,Fonte_Dati!D:D,D22),0) -> -315.94587 | J25: =IFERROR(SUMIFS(Fonte_Dati!I:I,Fonte_Dati!D:D,D22),0) -> 150090.73 | K25: =IFERROR(J22/G22,0) -> 114.4208 | L25: =IFERROR(J22*0.08,0) -> 83263.847 | M25: 96.26986 | N25: 6202
C26: 8 | D26: FV-Serre Narbone | E26: Fotovoltaico | F26: =IFERROR(SUMIFS(Fonte_Dati!E:E,Fonte_Dati!D:D,D23)/1000,0) -> 1503.9636 | G26: =IFERROR(SUMIFS(Fonte_Dati!F:F,Fonte_Dati!D:D,D23)/1000,0) -> 1538.5548 | H26: =IFERROR(SUMIFS(Fonte_Dati!G:G,Fonte_Dati!D:D,D23),0) -> 148356.71 | I26: =IFERROR(SUMIFS(Fonte_Dati!H:H,Fonte_Dati!D:D,D23),0) -> -307.71095 | J26: =IFERROR(SUMIFS(Fonte_Dati!I:I,Fonte_Dati!D:D,D23),0) -> 148049 | K26: =IFERROR(J23/G23,0) -> 111.85094 | L26: =IFERROR(J23*0.08,0) -> 72544.864 | M26: 95.157993 | N26: 6077
C27: 9 | D27: FV-Perniciara | E27: Fotovoltaico | F27: =IFERROR(SUMIFS(Fonte_Dati!E:E,Fonte_Dati!D:D,D24)/1000,0) -> 1146.8885 | G27: =IFERROR(SUMIFS(Fonte_Dati!F:F,Fonte_Dati!D:D,D24)/1000,0) -> 1142.3009 | H27: =IFERROR(SUMIFS(Fonte_Dati!G:G,Fonte_Dati!D:D,D24),0) -> 103510.6 | I27: =IFERROR(SUMIFS(Fonte_Dati!H:H,Fonte_Dati!D:D,D24),0) -> -228.46019 | J27: =IFERROR(SUMIFS(Fonte_Dati!I:I,Fonte_Dati!D:D,D24),0) -> 103282.14 | K27: =IFERROR(J24/G24,0) -> 112.61287 | L27: =IFERROR(J24*0.08,0) -> 35541.32 | M27: 95.146684 | N27: 4060
C28: 10 | D28: FV-Serre Gela | E28: Fotovoltaico | F28: =IFERROR(SUMIFS(Fonte_Dati!E:E,Fonte_Dati!D:D,D25)/1000,0) -> 787.1292 | G28: =IFERROR(SUMIFS(Fonte_Dati!F:F,Fonte_Dati!D:D,D25)/1000,0) -> 805.23317 | H28: =IFERROR(SUMIFS(Fonte_Dati!G:G,Fonte_Dati!D:D,D25),0) -> 77680.731 | I28: =IFERROR(SUMIFS(Fonte_Dati!H:H,Fonte_Dati!D:D,D25),0) -> -161.04663 | J28: =IFERROR(SUMIFS(Fonte_Dati!I:I,Fonte_Dati!D:D,D25),0) -> 77519.685 | K28: =IFERROR(J25/G25,0) -> 95.010406 | L28: =IFERROR(J25*0.08,0) -> 12007.258 | M28: 95.258757 | N28: 3718
C29: 11 | D29: FV-Malvizzo Piccolo | E29: Fotovoltaico | F29: =IFERROR(SUMIFS(Fonte_Dati!E:E,Fonte_Dati!D:D,D26)/1000,0) -> 801.5076 | G29: =IFERROR(SUMIFS(Fonte_Dati!F:F,Fonte_Dati!D:D,D26)/1000,0) -> 798.30157 | H29: =IFERROR(SUMIFS(Fonte_Dati!G:G,Fonte_Dati!D:D,D26),0) -> 76124.436 | I29: =IFERROR(SUMIFS(Fonte_Dati!H:H,Fonte_Dati!D:D,D26),0) -> -159.66031 | J29: =IFERROR(SUMIFS(Fonte_Dati!I:I,Fonte_Dati!D:D,D26),0) -> 75964.775 | K29: =IFERROR(J26/G26,0) -> 96.226018 | L29: =IFERROR(J26*0.08,0) -> 11843.92 | M29: 91.326377 | N29: 2374
C30: 12 | D30: FV-Malvizzo a Terra | E30: Fotovoltaico | F30: =IFERROR(SUMIFS(Fonte_Dati!E:E,Fonte_Dati!D:D,D27)/1000,0) -> 521.4165 | G30: =IFERROR(SUMIFS(Fonte_Dati!F:F,Fonte_Dati!D:D,D27)/1000,0) -> 533.40908 | H30: =IFERROR(SUMIFS(Fonte_Dati!G:G,Fonte_Dati!D:D,D27),0) -> 50858.787 | I30: =IFERROR(SUMIFS(Fonte_Dati!H:H,Fonte_Dati!D:D,D27),0) -> -106.68182 | J30: =IFERROR(SUMIFS(Fonte_Dati!I:I,Fonte_Dati!D:D,D27),0) -> 50752.105 | K30: =IFERROR(J27/G27,0) -> 90.415876 | L30: =IFERROR(J27*0.08,0) -> 8262.5711 | M30: 90.80157 | N30: 2319
C31: 13 | D31: FV-Narbone a Terra Grande | E31: Fotovoltaico | F31: =IFERROR(SUMIFS(Fonte_Dati!E:E,Fonte_Dati!D:D,D28)/1000,0) -> 476.96608 | G31: =IFERROR(SUMIFS(Fonte_Dati!F:F,Fonte_Dati!D:D,D28)/1000,0) -> 487.9363 | H31: =IFERROR(SUMIFS(Fonte_Dati!G:G,Fonte_Dati!D:D,D28),0) -> 46577.793 | I31: =IFERROR(SUMIFS(Fonte_Dati!H:H,Fonte_Dati!D:D,D28),0) -> -97.58726 | J31: =IFERROR(SUMIFS(Fonte_Dati!I:I,Fonte_Dati!D:D,D28),0) -> 46480.205 | K31: =IFERROR(J28/G28,0) -> 96.26986 | L31: =IFERROR(J28*0.08,0) -> 6201.5748 | M31: 115.00624 | N31: 698
C32: 14 | F32: =IFERROR(SUMIFS(Fonte_Dati!E:E,Fonte_Dati!D:D,D29)/1000,0) -> 326.17582 | G32: =IFERROR(SUMIFS(Fonte_Dati!F:F,Fonte_Dati!D:D,D29)/1000,0) -> 324.87112 | H32: =IFERROR(SUMIFS(Fonte_Dati!G:G,Fonte_Dati!D:D,D29),0) -> 29734.277 | I32: =IFERROR(SUMIFS(Fonte_Dati!H:H,Fonte_Dati!D:D,D29),0) -> -64.974224 | J32: =IFERROR(SUMIFS(Fonte_Dati!I:I,Fonte_Dati!D:D,D29),0) -> 29669.302 | K32: =IFERROR(J29/G29,0) -> 95.157993 | L32: =IFERROR(J29*0.08,0) -> 6077.182 | M32: 94.458118 | N32: 591
C33: 15 | D33: FV-Campofranco Tetto | E33: Fotovoltaico | F33: =IFERROR(SUMIFS(Fonte_Dati!E:E,Fonte_Dati!D:D,D30)/1000,0) -> 320.47704 | G33: =IFERROR(SUMIFS(Fonte_Dati!F:F,Fonte_Dati!D:D,D30)/1000,0) -> 319.19513 | H33: =IFERROR(SUMIFS(Fonte_Dati!G:G,Fonte_Dati!D:D,D30),0) -> 29047.258 | I33: =IFERROR(SUMIFS(Fonte_Dati!H:H,Fonte_Dati!D:D,D30),0) -> -63.839026 | J33: =IFERROR(SUMIFS(Fonte_Dati!I:I,Fonte_Dati!D:D,D30),0) -> 28983.419 | K33: =IFERROR(J30/G30,0) -> 95.146684 | L33: =IFERROR(J30*0.08,0) -> 4060.1684 | M33: 91.559736 | N33: 530
C34: 16 | D34: FV-Tumarrano MEG | E34: Fotovoltaico | F34: =IFERROR(SUMIFS(Fonte_Dati!E:E,Fonte_Dati!D:D,D31)/1000,0) -> 76.19016 | G34: =IFERROR(SUMIFS(Fonte_Dati!F:F,Fonte_Dati!D:D,D31)/1000,0) -> 75.885399 | H34: =IFERROR(SUMIFS(Fonte_Dati!G:G,Fonte_Dati!D:D,D31),0) -> 8742.4718 | I34: =IFERROR(SUMIFS(Fonte_Dati!H:H,Fonte_Dati!D:D,D31),0) -> -15.17708 | J34: =IFERROR(SUMIFS(Fonte_Dati!I:I,Fonte_Dati!D:D,D31),0) -> 8727.2947 | K34: =IFERROR(J31/G31,0) -> 95.258757 | L34: =IFERROR(J31*0.08,0) -> 3718.4164 | M34: 93.082199 | N34: 146
C35: TOTALE PORTFOLIO | F35: =SUM(F16:F31) -> 27930.679 | G35: =SUM(G16:G31) -> 28034.089 | H35: =SUM(H16:H31) -> 3049620.8 | I35: =SUM(I16:I31) -> -5606.8178 | J35: =SUM(J16:J31) -> 3044014 | K35: =IFERROR(J32/G32,0) -> 91.326377 | L35: =SUM(L16:L31) -> 229665.35

Sheet Produzione
B1: ⚡ PRODUZIONE ENERGETICA MENSILE — PORTFOLIO Q1 2026
B4: Energia Misurata (kWh→MWh) e Maggiorata per Impianto | Fonte: _Storico_Dati_
B6: ENERGIA MISURATA (MWh) — BREAKDOWN MENSILE | O6: PERFORMANCE RATIO (IEC 61724-1) — PR = E_real [kWh] / (H(i) [kWh/m²] × kWp DC)
B7: ID | C7: Impianto | D7: Tipo | E7: Gen 2026 (MWh) | F7: Feb 2026 (MWh) | G7: Mar 2026 (MWh) | H7: Totale Q1 (MWh) | I7: Gen/Tot % | J7: Gen vs Feb | K7: Feb vs Gen | L7: EUR/MWh Gen | M7: EUR/MWh Feb | N7: EUR/MWh Q1 | O7: kWp DC | P7: Irr. Gen (kWh/m²) | Q7: Irr. Feb (kWh/m²) | R7: Irr. Mar (kWh/m²) | S7: PR Gen (%) | T7: PR Feb (%) | U7: PR Mar (%) | V7: PR Q1 (%)
B8: 1 | C8: Wind - Monte Narbone | D8: Eolico | E8: =IFERROR(SUMIFS(Fonte_Dati!E:E,Fonte_Dati!D:D,C8,Fonte_Dati!C:C,"Gennaio")/1000,0) -> 4716.6952 | F8: =IFERROR(SUMIFS(Fonte_Dati!E:E,Fonte_Dati!D:D,C8,Fonte_Dati!C:C,"Febbraio")/1000,0) -> 4379.1799 | G8: =IFERROR(SUMIFS(Fonte_Dati!E:E,Fonte_Dati!D:D,C8,Fonte_Dati!C:C,"Marzo")/1000,0) -> 0.34854082 | H8: =SUM(E8:G8) -> 9096.2236 | I8: =IFERROR(E8/H8,0) -> 0.51853334 | J8: =IFERROR(F8-E8,0) -> -337.51536 | K8: =IFERROR((F8-E8)/E8,"-") -> -0.071557594 | L8: =IFERROR(SUMIFS(Fonte_Dati!I:I,Fonte_Dati!D:D,C8,Fonte_Dati!C:C,"Gennaio")/(SUMIFS(Fonte_Dati!F:F,Fonte_Dati!D:D,C8,Fonte_Dati!C:C,"Gennaio")/1000),0) -> 124.75426 | M8: =IFERROR(SUMIFS(Fonte_Dati!I:I,Fonte_Dati!D:D,C8,Fonte_Dati!C:C,"Febbraio")/(SUMIFS(Fonte_Dati!F:F,Fonte_Dati!D:D,C8,Fonte_Dati!C:C,"Febbraio")/1000),0) -> 103.29036 | N8: =IFERROR(SUMIFS(Fonte_Dati!I:I,Fonte_Dati!D:D,C8)/(SUMIFS(Fonte_Dati!F:F,Fonte_Dati!D:D,C8)/1000),0) -> 114.4208 | O8: =IFERROR(VLOOKUP(C8,DB_Impianti!C:K,9,0),"") -> 0 | P8: =IFERROR(VLOOKUP(C8,Irraggiamento_PVGIS!C50:H65,3,0),"") | Q8: =IFERROR(VLOOKUP(C8,Irraggiamento_PVGIS!C50:H65,4,0),"") | R8: =IFERROR(VLOOKUP(C8,Irraggiamento_PVGIS!C50:H65,5,0),"") | S8: =IFERROR((E8*1000)/(P8*O8),"") | T8: =IFERROR((F8*1000)/(Q8*O8),"") | U8: =IFERROR((G8*1000)/(R8*O8),"") | V8: =IFERROR((H8*1000)/(VLOOKUP(C8,Irraggiamento_PVGIS!C50:H65,6,0)*O8),"")
B9: 2 | C9: Wind - Monte Durrà | D9: Eolico | E9: =IFERROR(SUMIFS(Fonte_Dati!E:E,Fonte_Dati!D:D,C9,Fonte_Dati!C:C,"Gennaio")/1000,0) -> 3977.1227 | F9: =IFERROR(SUMIFS(Fonte_Dati!E:E,Fonte_Dati!D:D,C9,Fonte_Dati!C:C,"Febbraio")/1000,0) -> 4130.1921 | G9: =IFERROR(SUMIFS(Fonte_Dati!E:E,Fonte_Dati!D:D,C9,Fonte_Dati!C:C,"Marzo")/1000,0) -> 0 | H9: =SUM(E9:G9) -> 8107.3148 | I9: =IFERROR(E9/H9,0) -> 0.4905598 | J9: =IFERROR(F9-E9,0) -> 153.0694 | K9: =IFERROR((F9-E9)/E9,"-") -> 0.038487471 | L9: =IFERROR(SUMIFS(Fonte_Dati!I:I,Fonte_Dati!D:D,C9,Fonte_Dati!C:C,"Gennaio")/(SUMIFS(Fonte_Dati!F:F,Fonte_Dati!D:D,C9,Fonte_Dati!C:C,"Gennaio")/1000),0) -> 120.79263 | M9: =IFERROR(SUMIFS(Fonte_Dati!I:I,Fonte_Dati!D:D,C9,Fonte_Dati!C:C,"Febbraio")/(SUMIFS(Fonte_Dati!F:F,Fonte_Dati!D:D,C9,Fonte_Dati!C:C,"Febbraio")/1000),0) -> 103.24065 | N9: =IFERROR(SUMIFS(Fonte_Dati!I:I,Fonte_Dati!D:D,C9)/(SUMIFS(Fonte_Dati!F:F,Fonte_Dati!D:D,C9)/1000),0) -> 111.85094 | O9: =IFERROR(VLOOKUP(C9,DB_Impianti!C:K,9,0),"") -> 0 | P9: =IFERROR(VLOOKUP(C9,Irraggiamento_PVGIS!C50:H65,3,0),"") | Q9: =IFERROR(VLOOKUP(C9,Irraggiamento_PVGIS!C50:H65,4,0),"") | R9: =IFERROR(VLOOKUP(C9,Irraggiamento_PVGIS!C50:H65,5,0),"") | S9: =IFERROR((E9*1000)/(P9*O9),"") | T9: =IFERROR((F9*1000)/(Q9*O9),"") | U9: =IFERROR((G9*1000)/(R9*O9),"") | V9: =IFERROR((H9*1000)/(VLOOKUP(C9,Irraggiamento_PVGIS!C50:H65,6,0)*O9),"")
B10: 3 | C10: Wind - Monte Malvizzo | D10: Eolico | E10: =IFERROR(SUMIFS(Fonte_Dati!E:E,Fonte_Dati!D:D,C10,Fonte_Dati!C:C,"Gennaio")/1000,0) -> 1906.8542 | F10: =IFERROR(SUMIFS(Fonte_Dati!E:E,Fonte_Dati!D:D,C10,Fonte_Dati!C:C,"Febbraio")/1000,0) -> 2037.2792 | G10: =IFERROR(SUMIFS(Fonte_Dati!E:E,Fonte_Dati!D:D,C10,Fonte_Dati!C:C,"Marzo")/1000,0) -> 0.9229494 | H10: =SUM(E10:G10) -> 3945.0563 | I10: =IFERROR(E10/H10,0) -> 0.48335284 | J10: =IFERROR(F10-E10,0) -> 130.425 | K10: =IFERROR((F10-E10)/E10,"-") -> 0.068397996 | L10: =IFERROR(SUMIFS(Fonte_Dati!I:I,Fonte_Dati!D:D,C10,Fonte_Dati!C:C,"Gennaio")/(SUMIFS(Fonte_Dati!F:F,Fonte_Dati!D:D,C10,Fonte_Dati!C:C,"Gennaio")/1000),0) -> 119.02333 | M10: =IFERROR(SUMIFS(Fonte_Dati!I:I,Fonte_Dati!D:D,C10,Fonte_Dati!C:C,"Febbraio")/(SUMIFS(Fonte_Dati!F:F,Fonte_Dati!D:D,C10,Fonte_Dati!C:C,"Febbraio")/1000),0) -> 106.60879 | N10: =IFERROR(SUMIFS(Fonte_Dati!I:I,Fonte_Dati!D:D,C10)/(SUMIFS(Fonte_Dati!F:F,Fonte_Dati!D:D,C10)/1000),0) -> 112.61287 | O10: =IFERROR(VLOOKUP(C10,DB_Impianti!C:K,9,0),"") -> 0 | P10: =IFERROR(VLOOKUP(C10,Irraggiamento_PVGIS!C50:H65,3,0),"") | Q10: =IFERROR(VLOOKUP(C10,Irraggiamento_PVGIS!C50:H65,4,0),"") | R10: =IFERROR(VLOOKUP(C10,Irraggiamento_PVGIS!C50:H65,5,0),"") | S10: =IFERROR((E10*1000)/(P10*O10),"") | T10: =IFERROR((F10*1000)/(Q10*O10),"") | U10: =IFERROR((G10*1000)/(R10*O10),"") | V10: =IFERROR((H10*1000)/(VLOOKUP(C10,Irraggiamento_PVGIS!C50:H65,6,0)*O10),"")
B11: 4 | C11: FV-Favara Grande | D11: Fotovoltaico | E11: =IFERROR(SUMIFS(Fonte_Dati!E:E,Fonte_Dati!D:D,C11,Fonte_Dati!C:C,"Gennaio")/1000,0) -> 629.42576 | F11: =IFERROR(SUMIFS(Fonte_Dati!E:E,Fonte_Dati!D:D,C11,Fonte_Dati!C:C,"Febbraio")/1000,0) -> 914.78672 | G11: =IFERROR(SUMIFS(Fonte_Dati!E:E,Fonte_Dati!D:D,C11,Fonte_Dati!C:C,"Marzo")/1000,0) -> 0 | H11: =SUM(E11:G11) -> 1544.2125 | I11: =IFERROR(E11/H11,0) -> 0.40760308 | J11: =IFERROR(F11-E11,0) -> 285.36096 | K11: =IFERROR((F11-E11)/E11,"-") -> 0.45336715 | L11: =IFERROR(SUMIFS(Fonte_Dati!I:I,Fonte_Dati!D:D,C11,Fonte_Dati!C:C,"Gennaio")/(SUMIFS(Fonte_Dati!F:F,Fonte_Dati!D:D,C11,Fonte_Dati!C:C,"Gennaio")/1000),0) -> 119.01009 | M11: =IFERROR(SUMIFS(Fonte_Dati!I:I,Fonte_Dati!D:D,C11,Fonte_Dati!C:C,"Febbraio")/(SUMIFS(Fonte_Dati!F:F,Fonte_Dati!D:D,C11,Fonte_Dati!C:C,"Febbraio")/1000),0) -> 78.497243 | N11: =IFERROR(SUMIFS(Fonte_Dati!I:I,Fonte_Dati!D:D,C11)/(SUMIFS(Fonte_Dati!F:F,Fonte_Dati!D:D,C11)/1000),0) -> 95.010406 | O11: =IFERROR(VLOOKUP(C11,DB_Impianti!C:K,9,0),"") -> 0 | P11: =IFERROR(VLOOKUP(C11,Irraggiamento_PVGIS!C50:H65,3,0),"") -> 0 | Q11: =IFERROR(VLOOKUP(C11,Irraggiamento_PVGIS!C50:H65,4,0),"") -> 0 | R11: =IFERROR(VLOOKUP(C11,Irraggiamento_PVGIS!C50:H65,5,0),"") -> 0 | S11: =IFERROR((E11*1000)/(P11*O11),"") | T11: =IFERROR((F11*1000)/(Q11*O11),"") | U11: =IFERROR((G11*1000)/(R11*O11),"") | V11: =IFERROR((H11*1000)/(VLOOKUP(C11,Irraggiamento_PVGIS!C50:H65,6,0)*O11),"")
B12: 5 | C12: FV-Fauma Tetto | D12: Fotovoltaico | E12: =IFERROR(SUMIFS(Fonte_Dati!E:E,Fonte_Dati!D:D,C12,Fonte_Dati!C:C,"Gennaio")/1000,0) -> 652.4864 | F12: =IFERROR(SUMIFS(Fonte_Dati!E:E,Fonte_Dati!D:D,C12,Fonte_Dati!C:C,"Febbraio")/1000,0) -> 851.4772 | G12: =IFERROR(SUMIFS(Fonte_Dati!E:E,Fonte_Dati!D:D,C12,Fonte_Dati!C:C,"Marzo")/1000,0) -> 0 | H12: =SUM(E12:G12) -> 1503.9636 | I12: =IFERROR(E12/H12,0) -> 0.43384454 | J12: =IFERROR(F12-E12,0) -> 198.9908 | K12: =IFERROR((F12-E12)/E12,"-") -> 0.3049731 | L12: =IFERROR(SUMIFS(Fonte_Dati!I:I,Fonte_Dati!D:D,C12,Fonte_Dati!C:C,"Gennaio")/(SUMIFS(Fonte_Dati!F:F,Fonte_Dati!D:D,C12,Fonte_Dati!C:C,"Gennaio")/1000),0) -> 118.4055 | M12: =IFERROR(SUMIFS(Fonte_Dati!I:I,Fonte_Dati!D:D,C12,Fonte_Dati!C:C,"Febbraio")/(SUMIFS(Fonte_Dati!F:F,Fonte_Dati!D:D,C12,Fonte_Dati!C:C,"Febbraio")/1000),0) -> 79.229894 | N12: =IFERROR(SUMIFS(Fonte_Dati!I:I,Fonte_Dati!D:D,C12)/(SUMIFS(Fonte_Dati!F:F,Fonte_Dati!D:D,C12)/1000),0) -> 96.226018 | O12: =IFERROR(VLOOKUP(C12,DB_Impianti!C:K,9,0),"") -> 0 | P12: =IFERROR(VLOOKUP(C12,Irraggiamento_PVGIS!C50:H65,3,0),"") -> 0 | Q12: =IFERROR(VLOOKUP(C12,Irraggiamento_PVGIS!C50:H65,4,0),"") -> 0 | R12: =IFERROR(VLOOKUP(C12,Irraggiamento_PVGIS!C50:H65,5,0),"") -> 0 | S12: =IFERROR((E12*1000)/(P12*O12),"") | T12: =IFERROR((F12*1000)/(Q12*O12),"") | U12: =IFERROR((G12*1000)/(R12*O12),"") | V12: =IFERROR((H12*1000)/(VLOOKUP(C12,Irraggiamento_PVGIS!C50:H65,6,0)*O12),"")
B13: 6 | C13: FV-Batia S. Francesco | D13: Fotovoltaico | E13: =IFERROR(SUMIFS(Fonte_Dati!E:E,Fonte_Dati!D:D,C13,Fonte_Dati!C:C,"Gennaio")/1000,0) -> 425.76024 | F13: =IFERROR(SUMIFS(Fonte_Dati!E:E,Fonte_Dati!D:D,C13,Fonte_Dati!C:C,"Febbraio")/1000,0) -> 721.12824 | G13: =IFERROR(SUMIFS(Fonte_Dati!E:E,Fonte_Dati!D:D,C13,Fonte_Dati!C:C,"Marzo")/1000,0) -> 0 | H13: =SUM(E13:G13) -> 1146.8885 | I13: =IFERROR(E13/H13,0) -> 0.37123072 | J13: =IFERROR(F13-E13,0) -> 295.368 | K13: =IFERROR((F13-E13)/E13,"-") -> 0.69374256 | L13: =IFERROR(SUMIFS(Fonte_Dati!I:I,Fonte_Dati!D:D,C13,Fonte_Dati!C:C,"Gennaio")/(SUMIFS(Fonte_Dati!F:F,Fonte_Dati!D:D,C13,Fonte_Dati!C:C,"Gennaio")/1000),0) -> 111.65761 | M13: =IFERROR(SUMIFS(Fonte_Dati!I:I,Fonte_Dati!D:D,C13,Fonte_Dati!C:C,"Febbraio")/(SUMIFS(Fonte_Dati!F:F,Fonte_Dati!D:D,C13,Fonte_Dati!C:C,"Febbraio")/1000),0) -> 77.874575 | N13: =IFERROR(SUMIFS(Fonte_Dati!I:I,Fonte_Dati!D:D,C13)/(SUMIFS(Fonte_Dati!F:F,Fonte_Dati!D:D,C13)/1000),0) -> 90.415876 | O13: =IFERROR(VLOOKUP(C13,DB_Impianti!C:K,9,0),"") -> 0 | P13: =IFERROR(VLOOKUP(C13,Irraggiamento_PVGIS!C50:H65,3,0),"") -> 0 | Q13: =IFERROR(VLOOKUP(C13,Irraggiamento_PVGIS!C50:H65,4,0),"") -> 0 | R13: =IFERROR(VLOOKUP(C13,Irraggiamento_PVGIS!C50:H65,5,0),"") -> 0 | S13: =IFERROR((E13*1000)/(P13*O13),"") | T13: =IFERROR((F13*1000)/(Q13*O13),"") | U13: =IFERROR((G13*1000)/(R13*O13),"") | V13: =IFERROR((H13*1000)/(VLOOKUP(C13,Irraggiamento_PVGIS!C50:H65,6,0)*O13),"")
B14: 7 | C14: FV-Serre S.Angelo Muxaro | D14: Fotovoltaico | E14: =IFERROR(SUMIFS(Fonte_Dati!E:E,Fonte_Dati!D:D,C14,Fonte_Dati!C:C,"Gennaio")/1000,0) -> 356.1996 | F14: =IFERROR(SUMIFS(Fonte_Dati!E:E,Fonte_Dati!D:D,C14,Fonte_Dati!C:C,"Febbraio")/1000,0) -> 430.9296 | G14: =IFERROR(SUMIFS(Fonte_Dati!E:E,Fonte_Dati!D:D,C14,Fonte_Dati!C:C,"Marzo")/1000,0) -> 0 | H14: =SUM(E14:G14) -> 787.1292 | I14: =IFERROR(E14/H14,0) -> 0.45253003 | J14: =IFERROR(F14-E14,0) -> 74.73 | K14: =IFERROR((F14-E14)/E14,"-") -> 0.2097981 | L14: =IFERROR(SUMIFS(Fonte_Dati!I:I,Fonte_Dati!D:D,C14,Fonte_Dati!C:C,"Gennaio")/(SUMIFS(Fonte_Dati!F:F,Fonte_Dati!D:D,C14,Fonte_Dati!C:C,"Gennaio")/1000),0) -> 118.57365 | M14: =IFERROR(SUMIFS(Fonte_Dati!I:I,Fonte_Dati!D:D,C14,Fonte_Dati!C:C,"Febbraio")/(SUMIFS(Fonte_Dati!F:F,Fonte_Dati!D:D,C14,Fonte_Dati!C:C,"Febbraio")/1000),0) -> 77.833898 | N14: =IFERROR(SUMIFS(Fonte_Dati!I:I,Fonte_Dati!D:D,C14)/(SUMIFS(Fonte_Dati!F:F,Fonte_Dati!D:D,C14)/1000),0) -> 96.26986 | O14: =IFERROR(VLOOKUP(C14,DB_Impianti!C:K,9,0),"") -> 0 | P14: =IFERROR(VLOOKUP(C14,Irraggiamento_PVGIS!C50:H65,3,0),"") -> 0 | Q14: =IFERROR(VLOOKUP(C14,Irraggiamento_PVGIS!C50:H65,4,0),"") -> 0 | R14: =IFERROR(VLOOKUP(C14,Irraggiamento_PVGIS!C50:H65,5,0),"") -> 0 | S14: =IFERROR((E14*1000)/(P14*O14),"") | T14: =IFERROR((F14*1000)/(Q14*O14),"") | U14: =IFERROR((G14*1000)/(R14*O14),"") | V14: =IFERROR((H14*1000)/(VLOOKUP(C14,Irraggiamento_PVGIS!C50:H65,6,0)*O14),"")
B15: 8 | C15: FV-Serre Narbone | D15: Fotovoltaico | E15: =IFERROR(SUMIFS(Fonte_Dati!E:E,Fonte_Dati!D:D,C15,Fonte_Dati!C:C,"Gennaio")/1000,0) -> 353.3616 | F15: =IFERROR(SUMIFS(Fonte_Dati!E:E,Fonte_Dati!D:D,C15,Fonte_Dati!C:C,"Febbraio")/1000,0) -> 448.146 | G15: =IFERROR(SUMIFS(Fonte_Dati!E:E,Fonte_Dati!D:D,C15,Fonte_Dati!C:C,"Marzo")/1000,0) -> 0 | H15: =SUM(E15:G15) -> 801.5076 | I15: =IFERROR(E15/H15,0) -> 0.44087118 | J15: =IFERROR(F15-E15,0) -> 94.7844 | K15: =IFERROR((F15-E15)/E15,"-") -> 0.26823628 | L15: =IFERROR(SUMIFS(Fonte_Dati!I:I,Fonte_Dati!D:D,C15,Fonte_Dati!C:C,"Gennaio")/(SUMIFS(Fonte_Dati!F:F,Fonte_Dati!D:D,C15,Fonte_Dati!C:C,"Gennaio")/1000),0) -> 117.94612 | M15: =IFERROR(SUMIFS(Fonte_Dati!I:I,Fonte_Dati!D:D,C15,Fonte_Dati!C:C,"Febbraio")/(SUMIFS(Fonte_Dati!F:F,Fonte_Dati!D:D,C15,Fonte_Dati!C:C,"Febbraio")/1000),0) -> 77.189631 | N15: =IFERROR(SUMIFS(Fonte_Dati!I:I,Fonte_Dati!D:D,C15)/(SUMIFS(Fonte_Dati!F:F,Fonte_Dati!D:D,C15)/1000),0) -> 95.157993 | O15: =IFERROR(VLOOKUP(C15,DB_Impianti!C:K,9,0),"") -> 0 | P15: =IFERROR(VLOOKUP(C15,Irraggiamento_PVGIS!C50:H65,3,0),"") -> 0 | Q15: =IFERROR(VLOOKUP(C15,Irraggiamento_PVGIS!C50:H65,4,0),"") -> 0 | R15: =IFERROR(VLOOKUP(C15,Irraggiamento_PVGIS!C50:H65,5,0),"") -> 0 | S15: =IFERROR((E15*1000)/(P15*O15),"") | T15: =IFERROR((F15*1000)/(Q15*O15),"") | U15: =IFERROR((G15*1000)/(R15*O15),"") | V15: =IFERROR((H15*1000)/(VLOOKUP(C15,Irraggiamento_PVGIS!C50:H65,6,0)*O15),"")
B16: 9 | C16: FV-Perniciara | D16: Fotovoltaico | E16: =IFERROR(SUMIFS(Fonte_Dati!E:E,Fonte_Dati!D:D,C16,Fonte_Dati!C:C,"Gennaio")/1000,0) -> 209.75475 | F16: =IFERROR(SUMIFS(Fonte_Dati!E:E,Fonte_Dati!D:D,C16,Fonte_Dati!C:C,"Febbraio")/1000,0) -> 311.66175 | G16: =IFERROR(SUMIFS(Fonte_Dati!E:E,Fonte_Dati!D:D,C16,Fonte_Dati!C:C,"Marzo")/1000,0) -> 0 | H16: =SUM(E16:G16) -> 521.4165 | I16: =IFERROR(E16/H16,0) -> 0.4022787 | J16: =IFERROR(F16-E16,0) -> 101.907 | K16: =IFERROR((F16-E16)/E16,"-") -> 0.48583882 | L16: =IFERROR(SUMIFS(Fonte_Dati!I:I,Fonte_Dati!D:D,C16,Fonte_Dati!C:C,"Gennaio")/(SUMIFS(Fonte_Dati!F:F,Fonte_Dati!D:D,C16,Fonte_Dati!C:C,"Gennaio")/1000),0) -> 119.24838 | M16: =IFERROR(SUMIFS(Fonte_Dati!I:I,Fonte_Dati!D:D,C16,Fonte_Dati!C:C,"Febbraio")/(SUMIFS(Fonte_Dati!F:F,Fonte_Dati!D:D,C16,Fonte_Dati!C:C,"Febbraio")/1000),0) -> 78.925747 | N16: =IFERROR(SUMIFS(Fonte_Dati!I:I,Fonte_Dati!D:D,C16)/(SUMIFS(Fonte_Dati!F:F,Fonte_Dati!D:D,C16)/1000),0) -> 95.146684 | O16: =IFERROR(VLOOKUP(C16,DB_Impianti!C:K,9,0),"") -> 0 | P16: =IFERROR(VLOOKUP(C16,Irraggiamento_PVGIS!C50:H65,3,0),"") -> 0 | Q16: =IFERROR(VLOOKUP(C16,Irraggiamento_PVGIS!C50:H65,4,0),"") -> 0 | R16: =IFERROR(VLOOKUP(C16,Irraggiamento_PVGIS!C50:H65,5,0),"") -> 0 | S16: =IFERROR((E16*1000)/(P16*O16),"") | T16: =IFERROR((F16*1000)/(Q16*O16),"") | U16: =IFERROR((G16*1000)/(R16*O16),"") | V16: =IFERROR((H16*1000)/(VLOOKUP(C16,Irraggiamento_PVGIS!C50:H65,6,0)*O16),"")
B17: 10 | C17: FV-Serre Gela | D17: Fotovoltaico | E17: =IFERROR(SUMIFS(Fonte_Dati!E:E,Fonte_Dati!D:D,C17,Fonte_Dati!C:C,"Gennaio")/1000,0) -> 199.29456 | F17: =IFERROR(SUMIFS(Fonte_Dati!E:E,Fonte_Dati!D:D,C17,Fonte_Dati!C:C,"Febbraio")/1000,0) -> 277.67152 | G17: =IFERROR(SUMIFS(Fonte_Dati!E:E,Fonte_Dati!D:D,C17,Fonte_Dati!C:C,"Marzo")/1000,0) -> 0 | H17: =SUM(E17:G17) -> 476.96608 | I17: =IFERROR(E17/H17,0) -> 0.41783801 | J17: =IFERROR(F17-E17,0) -> 78.37696 | K17: =IFERROR((F17-E17)/E17,"-") -> 0.39327195 | L17: =IFERROR(SUMIFS(Fonte_Dati!I:I,Fonte_Dati!D:D,C17,Fonte_Dati!C:C,"Gennaio")/(SUMIFS(Fonte_Dati!F:F,Fonte_Dati!D:D,C17,Fonte_Dati!C:C,"Gennaio")/1000),0) -> 117.62235 | M17: =IFERROR(SUMIFS(Fonte_Dati!I:I,Fonte_Dati!D:D,C17,Fonte_Dati!C:C,"Febbraio")/(SUMIFS(Fonte_Dati!F:F,Fonte_Dati!D:D,C17,Fonte_Dati!C:C,"Febbraio")/1000),0) -> 79.207626 | N17: =IFERROR(SUMIFS(Fonte_Dati!I:I,Fonte_Dati!D:D,C17)/(SUMIFS(Fonte_Dati!F:F,Fonte_Dati!D:D,C17)/1000),0) -> 95.258757 | O17: =IFERROR(VLOOKUP(C17,DB_Impianti!C:K,9,0),"") -> 0 | P17: =IFERROR(VLOOKUP(C17,Irraggiamento_PVGIS!C50:H65,3,0),"") -> 0 | Q17: =IFERROR(VLOOKUP(C17,Irraggiamento_PVGIS!C50:H65,4,0),"") -> 0 | R17: =IFERROR(VLOOKUP(C17,Irraggiamento_PVGIS!C50:H65,5,0),"") -> 0 | S17: =IFERROR((E17*1000)/(P17*O17),"") | T17: =IFERROR((F17*1000)/(Q17*O17),"") | U17: =IFERROR((G17*1000)/(R17*O17),"") | V17: =IFERROR((H17*1000)/(VLOOKUP(C17,Irraggiamento_PVGIS!C50:H65,6,0)*O17),"")
B18: 11 | C18: FV-Malvizzo Piccolo | D18: Fotovoltaico | E18: =IFERROR(SUMIFS(Fonte_Dati!E:E,Fonte_Dati!D:D,C18,Fonte_Dati!C:C,"Gennaio")/1000,0) -> 111.37613 | F18: =IFERROR(SUMIFS(Fonte_Dati!E:E,Fonte_Dati!D:D,C18,Fonte_Dati!C:C,"Febbraio")/1000,0) -> 214.7997 | G18: =IFERROR(SUMIFS(Fonte_Dati!E:E,Fonte_Dati!D:D,C18,Fonte_Dati!C:C,"Marzo")/1000,0) -> 0 | H18: =SUM(E18:G18) -> 326.17582 | I18: =IFERROR(E18/H18,0) -> 0.34146039 | J18: =IFERROR(F18-E18,0) -> 103.42357 | K18: =IFERROR((F18-E18)/E18,"-") -> 0.92859735 | L18: =IFERROR(SUMIFS(Fonte_Dati!I:I,Fonte_Dati!D:D,C18,Fonte_Dati!C:C,"Gennaio")/(SUMIFS(Fonte_Dati!F:F,Fonte_Dati!D:D,C18,Fonte_Dati!C:C,"Gennaio")/1000),0) -> 110.50325 | M18: =IFERROR(SUMIFS(Fonte_Dati!I:I,Fonte_Dati!D:D,C18,Fonte_Dati!C:C,"Febbraio")/(SUMIFS(Fonte_Dati!F:F,Fonte_Dati!D:D,C18,Fonte_Dati!C:C,"Febbraio")/1000),0) -> 81.382945 | N18: =IFERROR(SUMIFS(Fonte_Dati!I:I,Fonte_Dati!D:D,C18)/(SUMIFS(Fonte_Dati!F:F,Fonte_Dati!D:D,C18)/1000),0) -> 91.326377 | O18: =IFERROR(VLOOKUP(C18,DB_Impianti!C:K,9,0),"") -> 0 | P18: =IFERROR(VLOOKUP(C18,Irraggiamento_PVGIS!C50:H65,3,0),"") -> 0 | Q18: =IFERROR(VLOOKUP(C18,Irraggiamento_PVGIS!C50:H65,4,0),"") -> 0 | R18: =IFERROR(VLOOKUP(C18,Irraggiamento_PVGIS!C50:H65,5,0),"") -> 0 | S18: =IFERROR((E18*1000)/(P18*O18),"") | T18: =IFERROR((F18*1000)/(Q18*O18),"") | U18: =IFERROR((G18*1000)/(R18*O18),"") | V18: =IFERROR((H18*1000)/(VLOOKUP(C18,Irraggiamento_PVGIS!C50:H65,6,0)*O18),"")
B19: 12 | C19: FV-Malvizzo a Terra | D19: Fotovoltaico | E19: =IFERROR(SUMIFS(Fonte_Dati!E:E,Fonte_Dati!D:D,C19,Fonte_Dati!C:C,"Gennaio")/1000,0) -> 112.0692 | F19: =IFERROR(SUMIFS(Fonte_Dati!E:E,Fonte_Dati!D:D,C19,Fonte_Dati!C:C,"Febbraio")/1000,0) -> 208.40784 | G19: =IFERROR(SUMIFS(Fonte_Dati!E:E,Fonte_Dati!D:D,C19,Fonte_Dati!C:C,"Marzo")/1000,0) -> 0 | H19: =SUM(E19:G19) -> 320.47704 | I19: =IFERROR(E19/H19,0) -> 0.34969494 | J19: =IFERROR(F19-E19,0) -> 96.33864 | K19: =IFERROR((F19-E19)/E19,"-") -> 0.8596353 | L19: =IFERROR(SUMIFS(Fonte_Dati!I:I,Fonte_Dati!D:D,C19,Fonte_Dati!C:C,"Gennaio")/(SUMIFS(Fonte_Dati!F:F,Fonte_Dati!D:D,C19,Fonte_Dati!C:C,"Gennaio")/1000),0) -> 109.09545 | M19: =IFERROR(SUMIFS(Fonte_Dati!I:I,Fonte_Dati!D:D,C19,Fonte_Dati!C:C,"Febbraio")/(SUMIFS(Fonte_Dati!F:F,Fonte_Dati!D:D,C19,Fonte_Dati!C:C,"Febbraio")/1000),0) -> 80.96422 | N19: =IFERROR(SUMIFS(Fonte_Dati!I:I,Fonte_Dati!D:D,C19)/(SUMIFS(Fonte_Dati!F:F,Fonte_Dati!D:D,C19)/1000),0) -> 90.80157 | O19: =IFERROR(VLOOKUP(C19,DB_Impianti!C:K,9,0),"") -> 0 | P19: =IFERROR(VLOOKUP(C19,Irraggiamento_PVGIS!C50:H65,3,0),"") -> 0 | Q19: =IFERROR(VLOOKUP(C19,Irraggiamento_PVGIS!C50:H65,4,0),"") -> 0 | R19: =IFERROR(VLOOKUP(C19,Irraggiamento_PVGIS!C50:H65,5,0),"") -> 0 | S19: =IFERROR((E19*1000)/(P19*O19),"") | T19: =IFERROR((F19*1000)/(Q19*O19),"") | U19: =IFERROR((G19*1000)/(R19*O19),"") | V19: =IFERROR((H19*1000)/(VLOOKUP(C19,Irraggiamento_PVGIS!C50:H65,6,0)*O19),"")
B20: 13 | C20: FV-Narbone a Terra Grande | D20: Fotovoltaico | E20: =IFERROR(SUMIFS(Fonte_Dati!E:E,Fonte_Dati!D:D,C20,Fonte_Dati!C:C,"Gennaio")/1000,0) -> 76.19016 | F20: =IFERROR(SUMIFS(Fonte_Dati!E:E,Fonte_Dati!D:D,C20,Fonte_Dati!C:C,"Febbraio")/1000,0) -> 0 | G20: =IFERROR(SUMIFS(Fonte_Dati!E:E,Fonte_Dati!D:D,C20,Fonte_Dati!C:C,"Marzo")/1000,0) -> 0 | H20: =SUM(E20:G20) -> 76.19016 | I20: =IFERROR(E20/H20,0) -> 1 | J20: =IFERROR(F20-E20,0) -> -76.19016 | K20: =IFERROR((F20-E20)/E20,"-") -> -1 | L20: =IFERROR(SUMIFS(Fonte_Dati!I:I,Fonte_Dati!D:D,C20,Fonte_Dati!C:C,"Gennaio")/(SUMIFS(Fonte_Dati!F:F,Fonte_Dati!D:D,C20,Fonte_Dati!C:C,"Gennaio")/1000),0) -> 115.00624 | M20: =IFERROR(SUMIFS(Fonte_Dati!I:I,Fonte_Dati!D:D,C20,Fonte_Dati!C:C,"Febbraio")/(SUMIFS(Fonte_Dati!F:F,Fonte_Dati!D:D,C20,Fonte_Dati!C:C,"Febbraio")/1000),0) -> 0 | N20: =IFERROR(SUMIFS(Fonte_Dati!I:I,Fonte_Dati!D:D,C20)/(SUMIFS(Fonte_Dati!F:F,Fonte_Dati!D:D,C20)/1000),0) -> 115.00624 | O20: =IFERROR(VLOOKUP(C20,DB_Impianti!C:K,9,0),"") -> 0 | P20: =IFERROR(VLOOKUP(C20,Irraggiamento_PVGIS!C50:H65,3,0),"") -> 0 | Q20: =IFERROR(VLOOKUP(C20,Irraggiamento_PVGIS!C50:H65,4,0),"") -> 0 | R20: =IFERROR(VLOOKUP(C20,Irraggiamento_PVGIS!C50:H65,5,0),"") -> 0 | S20: =IFERROR((E20*1000)/(P20*O20),"") | T20: =IFERROR((F20*1000)/(Q20*O20),"") | U20: =IFERROR((G20*1000)/(R20*O20),"") | V20: =IFERROR((H20*1000)/(VLOOKUP(C20,Irraggiamento_PVGIS!C50:H65,6,0)*O20),"")
B21: 14 | C21: FV-Narbone Piccolo | D21: Fotovoltaico | E21: =IFERROR(SUMIFS(Fonte_Dati!E:E,Fonte_Dati!D:D,C21,Fonte_Dati!C:C,"Gennaio")/1000,0) -> 33.2097 | F21: =IFERROR(SUMIFS(Fonte_Dati!E:E,Fonte_Dati!D:D,C21,Fonte_Dati!C:C,"Febbraio")/1000,0) -> 45.30684 | G21: =IFERROR(SUMIFS(Fonte_Dati!E:E,Fonte_Dati!D:D,C21,Fonte_Dati!C:C,"Marzo")/1000,0) -> 0 | H21: =SUM(E21:G21) -> 78.51654 | I21: =IFERROR(E21/H21,0) -> 0.42296438 | J21: =IFERROR(F21-E21,0) -> 12.09714 | K21: =IFERROR((F21-E21)/E21,"-") -> 0.36426526 | L21: =IFERROR(SUMIFS(Fonte_Dati!I:I,Fonte_Dati!D:D,C21,Fonte_Dati!C:C,"Gennaio")/(SUMIFS(Fonte_Dati!F:F,Fonte_Dati!D:D,C21,Fonte_Dati!C:C,"Gennaio")/1000),0) -> 116.80923 | M21: =IFERROR(SUMIFS(Fonte_Dati!I:I,Fonte_Dati!D:D,C21,Fonte_Dati!C:C,"Febbraio")/(SUMIFS(Fonte_Dati!F:F,Fonte_Dati!D:D,C21,Fonte_Dati!C:C,"Febbraio")/1000),0) -> 78.074857 | N21: =IFERROR(SUMIFS(Fonte_Dati!I:I,Fonte_Dati!D:D,C21)/(SUMIFS(Fonte_Dati!F:F,Fonte_Dati!D:D,C21)/1000),0) -> 94.458118 | O21: =IFERROR(VLOOKUP(C21,DB_Impianti!C:K,9,0),"") -> 0 | P21: =IFERROR(VLOOKUP(C21,Irraggiamento_PVGIS!C50:H65,3,0),"") -> 0 | Q21: =IFERROR(VLOOKUP(C21,Irraggiamento_PVGIS!C50:H65,4,0),"") -> 0 | R21: =IFERROR(VLOOKUP(C21,Irraggiamento_PVGIS!C50:H65,5,0),"") -> 0 | S21: =IFERROR((E21*1000)/(P21*O21),"") | T21: =IFERROR((F21*1000)/(Q21*O21),"") | U21: =IFERROR((G21*1000)/(R21*O21),"") | V21: =IFERROR((H21*1000)/(VLOOKUP(C21,Irraggiamento_PVGIS!C50:H65,6,0)*O21),"")
B22: 15 | C22: FV-Campofranco Tetto | D22: Fotovoltaico | E22: =IFERROR(SUMIFS(Fonte_Dati!E:E,Fonte_Dati!D:D,C22,Fonte_Dati!C:C,"Gennaio")/1000,0) -> 24.29524 | F22: =IFERROR(SUMIFS(Fonte_Dati!E:E,Fonte_Dati!D:D,C22,Fonte_Dati!C:C,"Febbraio")/1000,0) -> 46.40668 | G22: =IFERROR(SUMIFS(Fonte_Dati!E:E,Fonte_Dati!D:D,C22,Fonte_Dati!C:C,"Marzo")/1000,0) -> 0 | H22: =SUM(E22:G22) -> 70.70192 | I22: =IFERROR(E22/H22,0) -> 0.34362914 | J22: =IFERROR(F22-E22,0) -> 22.11144 | K22: =IFERROR((F22-E22)/E22,"-") -> 0.91011408 | L22: =IFERROR(SUMIFS(Fonte_Dati!I:I,Fonte_Dati!D:D,C22,Fonte_Dati!C:C,"Gennaio")/(SUMIFS(Fonte_Dati!F:F,Fonte_Dati!D:D,C22,Fonte_Dati!C:C,"Gennaio")/1000),0) -> 121.51592 | M22: =IFERROR(SUMIFS(Fonte_Dati!I:I,Fonte_Dati!D:D,C22,Fonte_Dati!C:C,"Febbraio")/(SUMIFS(Fonte_Dati!F:F,Fonte_Dati!D:D,C22,Fonte_Dati!C:C,"Febbraio")/1000),0) -> 75.876805 | N22: =IFERROR(SUMIFS(Fonte_Dati!I:I,Fonte_Dati!D:D,C22)/(SUMIFS(Fonte_Dati!F:F,Fonte_Dati!D:D,C22)/1000),0) -> 91.559736 | O22: =IFERROR(VLOOKUP(C22,DB_Impianti!C:K,9,0),"") -> 0 | P22: =IFERROR(VLOOKUP(C22,Irraggiamento_PVGIS!C50:H65,3,0),"") -> 0 | Q22: =IFERROR(VLOOKUP(C22,Irraggiamento_PVGIS!C50:H65,4,0),"") -> 0 | R22: =IFERROR(VLOOKUP(C22,Irraggiamento_PVGIS!C50:H65,5,0),"") -> 0 | S22: =IFERROR((E22*1000)/(P22*O22),"") | T22: =IFERROR((F22*1000)/(Q22*O22),"") | U22: =IFERROR((G22*1000)/(R22*O22),"") | V22: =IFERROR((H22*1000)/(VLOOKUP(C22,Irraggiamento_PVGIS!C50:H65,6,0)*O22),"")
B23: 16 | C23: FV-Tumarrano MEG | D23: Fotovoltaico | E23: =IFERROR(SUMIFS(Fonte_Dati!E:E,Fonte_Dati!D:D,C23,Fonte_Dati!C:C,"Gennaio")/1000,0) -> 7.469178 | F23: =IFERROR(SUMIFS(Fonte_Dati!E:E,Fonte_Dati!D:D,C23,Fonte_Dati!C:C,"Febbraio")/1000,0) -> 11.697042 | G23: =IFERROR(SUMIFS(Fonte_Dati!E:E,Fonte_Dati!D:D,C23,Fonte_Dati!C:C,"Marzo")/1000,0) -> 0 | H23: =SUM(E23:G23) -> 19.16622 | I23: =IFERROR(E23/H23,0) -> 0.38970533 | J23: =IFERROR(F23-E23,0) -> 4.227864 | K23: =IFERROR((F23-E23)/E23,"-") -> 0.5660414 | L23: =IFERROR(SUMIFS(Fonte_Dati!I:I,Fonte_Dati!D:D,C23,Fonte_Dati!C:C,"Gennaio")/(SUMIFS(Fonte_Dati!F:F,Fonte_Dati!D:D,C23,Fonte_Dati!C:C,"Gennaio")/1000),0) -> 117.67705 | M23: =IFERROR(SUMIFS(Fonte_Dati!I:I,Fonte_Dati!D:D,C23,Fonte_Dati!C:C,"Febbraio")/(SUMIFS(Fonte_Dati!F:F,Fonte_Dati!D:D,C23,Fonte_Dati!C:C,"Febbraio")/1000),0) -> 77.377091 | N23: =IFERROR(SUMIFS(Fonte_Dati!I:I,Fonte_Dati!D:D,C23)/(SUMIFS(Fonte_Dati!F:F,Fonte_Dati!D:D,C23)/1000),0) -> 93.082199 | O23: =IFERROR(VLOOKUP(C23,DB_Impianti!C:K,9,0),"") -> 0 | P23: =IFERROR(VLOOKUP(C23,Irraggiamento_PVGIS!C50:H65,3,0),"") -> 0 | Q23: =IFERROR(VLOOKUP(C23,Irraggiamento_PVGIS!C50:H65,4,0),"") -> 0 | R23: =IFERROR(VLOOKUP(C23,Irraggiamento_PVGIS!C50:H65,5,0),"") -> 0 | S23: =IFERROR((E23*1000)/(P23*O23),"") | T23: =IFERROR((F23*1000)/(Q23*O23),"") | U23: =IFERROR((G23*1000)/(R23*O23),"") | V23: =IFERROR((H23*1000)/(VLOOKUP(C23,Irraggiamento_PVGIS!C50:H65,6,0)*O23),"")
B24: TOTALE Q1 2026 | E24: =SUM(E8:E23) -> 13791.565 | F24: =SUM(F8:F23) -> 15029.07 | G24: =SUM(G8:G23) -> 1.2714902 | H24: =SUM(H8:H23) -> 28821.906 | M24: =IFERROR(J24/G24,0) -> 0 | O24: =IFERROR(SUM(O8:O23),"") -> 0 | S24: =IFERROR(AVERAGE(S8:S23),"") | T24: =IFERROR(AVERAGE(T8:T23),"") | U24: =IFERROR(AVERAGE(U8:U23),"") | V24: =IFERROR(AVERAGE(V8:V23),"")
O25: ⚠ PR calcolato solo se kWp DC inserito in DB_Impianti col K
B26: BREAKDOWN FV vs EOLICO
B27: Fotovoltaico (13 imp.) | E27: =E11+E12+E13+E14+E15+E16+E17+E18+E19+E20+E21+E22+E23 -> 3190.8925 | F27: =F11+F12+F13+F14+F15+F16+F17+F18+F19+F20+F21+F22+F23 -> 4482.4191 | G27: =G11+G12+G13+G14+G15+G16+G17+G18+G19+G20+G21+G22+G23 -> 0 | H27: =H11+H12+H13+H14+H15+H16+H17+H18+H19+H20+H21+H22+H23 -> 7673.3116
B28: Eolico (3 imp.) | E28: =E8+E9+E10 -> 10600.672 | F28: =F8+F9+F10 -> 10546.651 | G28: =G8+G9+G10 -> 1.2714902 | H28: =H8+H9+H10 -> 21148.595
B29: Totale Portfolio | E29: =E27+E28 -> 13791.565 | F29: =F27+F28 -> 15029.07 | G29: =G27+G28 -> 1.2714902 | H29: =H27+H28 -> 28821.906

Sheet Fatturazione
B1: 💳 FATTURAZIONE DETTAGLIO — PER IMPIANTO E MESE
B4: Dettaglio mensile: Energia, Fee, Prezzo e Totale Fatturato | Q1 2026
B6: ID | C6: Impianto | D6: Tipo | E6: Trader | F6: Ragione Sociale | G6: PVI | H6: Fee (€/MWh) | I6: Mese | J6: MWh Mis. | K6: MWh Magg. | L6: Fat. Lordo (€) | M6: Fee App. (€) | N6: Fat. Netto (€) | O6: EUR/MWh Netto
B7: 1 | C7: Wind - Monte Narbone | D7: Eolico | E7: =IFERROR(VLOOKUP(C7,DB_Impianti!C:E,3,0),"") -> DXT | F7: =IFERROR(VLOOKUP(C7,DB_Impianti!C:F,4,0),"") -> Moncada Energy Group Srl | G7: =IFERROR(VLOOKUP(C7,DB_Impianti!C:G,5,0),"") -> PVI_S19MNEN_001 | H7: =IFERROR(VLOOKUP(C7,DB_Impianti!C:H,6,0),0) -> -1.36 | I7: Gennaio 2026 | J7: =IFERROR(SUMIFS(Fonte_Dati!E:E,Fonte_Dati!D:D,C7,Fonte_Dati!C:C,"Gennaio")/1000,0) -> 4716.6952 | K7: =IFERROR(SUMIFS(Fonte_Dati!F:F,Fonte_Dati!D:D,C7,Fonte_Dati!C:C,"Gennaio")/1000,0) -> 4716.6952 | L7: =IFERROR(SUMIFS(Fonte_Dati!G:G,Fonte_Dati!D:D,C7,Fonte_Dati!C:C,"Gennaio"),0) -> 589371.14 | M7: =IFERROR(SUMIFS(Fonte_Dati!H:H,Fonte_Dati!D:D,C7,Fonte_Dati!C:C,"Gennaio"),0) -> -943.33904 | N7: =IFERROR(SUMIFS(Fonte_Dati!I:I,Fonte_Dati!D:D,C7,Fonte_Dati!C:C,"Gennaio"),0) -> 588427.8 | O7: =IFERROR(N7/K7,0) -> 124.75426
B8: 1 | C8: Wind - Monte Narbone | D8: Eolico | E8: =IFERROR(VLOOKUP(C8,DB_Impianti!C:E,3,0),"") -> DXT | F8: =IFERROR(VLOOKUP(C8,DB_Impianti!C:F,4,0),"") -> Moncada Energy Group Srl | G8: =IFERROR(VLOOKUP(C8,DB_Impianti!C:G,5,0),"") -> PVI_S19MNEN_001 | H8: =IFERROR(VLOOKUP(C8,DB_Impianti!C:H,6,0),0) -> -1.36 | I8: Febbraio 2026 | J8: =IFERROR(SUMIFS(Fonte_Dati!E:E,Fonte_Dati!D:D,C8,Fonte_Dati!C:C,"Febbraio")/1000,0) -> 4379.1799 | K8: =IFERROR(SUMIFS(Fonte_Dati!F:F,Fonte_Dati!D:D,C8,Fonte_Dati!C:C,"Febbraio")/1000,0) -> 4379.1799 | L8: =IFERROR(SUMIFS(Fonte_Dati!G:G,Fonte_Dati!D:D,C8,Fonte_Dati!C:C,"Febbraio"),0) -> 453202.88 | M8: =IFERROR(SUMIFS(Fonte_Dati!H:H,Fonte_Dati!D:D,C8,Fonte_Dati!C:C,"Febbraio"),0) -> -875.83597 | N8: =IFERROR(SUMIFS(Fonte_Dati!I:I,Fonte_Dati!D:D,C8,Fonte_Dati!C:C,"Febbraio"),0) -> 452327.04 | O8: =IFERROR(N8/K8,0) -> 103.29036
B9: 1 | C9: Wind - Monte Narbone | D9: Eolico | E9: =IFERROR(VLOOKUP(C9,DB_Impianti!C:E,3,0),"") -> DXT | F9: =IFERROR(VLOOKUP(C9,DB_Impianti!C:F,4,0),"") -> Moncada Energy Group Srl | G9: =IFERROR(VLOOKUP(C9,DB_Impianti!C:G,5,0),"") -> PVI_S19MNEN_001 | H9: =IFERROR(VLOOKUP(C9,DB_Impianti!C:H,6,0),0) -> -1.36 | I9: Marzo 2026 | J9: =IFERROR(SUMIFS(Fonte_Dati!E:E,Fonte_Dati!D:D,C9,Fonte_Dati!C:C,"Marzo")/1000,0) -> 0.34854082 | K9: =IFERROR(SUMIFS(Fonte_Dati!F:F,Fonte_Dati!D:D,C9,Fonte_Dati!C:C,"Marzo")/1000,0) -> 0.35655726 | L9: =IFERROR(SUMIFS(Fonte_Dati!G:G,Fonte_Dati!D:D,C9,Fonte_Dati!C:C,"Marzo"),0) -> 43.314576 | M9: =IFERROR(SUMIFS(Fonte_Dati!H:H,Fonte_Dati!D:D,C9,Fonte_Dati!C:C,"Marzo"),0) -> -0.071311452 | N9: =IFERROR(SUMIFS(Fonte_Dati!I:I,Fonte_Dati!D:D,C9,Fonte_Dati!C:C,"Marzo"),0) -> 43.243264 | O9: =IFERROR(N9/K9,0) -> 121.28
B10: 2 | C10: Wind - Monte Durrà | D10: Eolico | E10: =IFERROR(VLOOKUP(C10,DB_Impianti!C:E,3,0),"") -> BANCO ENERGIA | F10: =IFERROR(VLOOKUP(C10,DB_Impianti!C:F,4,0),"") -> Moncada Energy Group Srl | G10: =IFERROR(VLOOKUP(C10,DB_Impianti!C:G,5,0),"") -> PVI_S19MDEN_001 | H10: =IFERROR(VLOOKUP(C10,DB_Impianti!C:H,6,0),0) -> -1.86 | I10: Gennaio 2026 | J10: =IFERROR(SUMIFS(Fonte_Dati!E:E,Fonte_Dati!D:D,C10,Fonte_Dati!C:C,"Gennaio")/1000,0) -> 3977.1227 | K10: =IFERROR(SUMIFS(Fonte_Dati!F:F,Fonte_Dati!D:D,C10,Fonte_Dati!C:C,"Gennaio")/1000,0) -> 3977.1227 | L10: =IFERROR(SUMIFS(Fonte_Dati!G:G,Fonte_Dati!D:D,C10,Fonte_Dati!C:C,"Gennaio"),0) -> 481202.52 | M10: =IFERROR(SUMIFS(Fonte_Dati!H:H,Fonte_Dati!D:D,C10,Fonte_Dati!C:C,"Gennaio"),0) -> -795.42454 | N10: =IFERROR(SUMIFS(Fonte_Dati!I:I,Fonte_Dati!D:D,C10,Fonte_Dati!C:C,"Gennaio"),0) -> 480407.1 | O10: =IFERROR(N10/K10,0) -> 120.79263
B11: 2 | C11: Wind - Monte Durrà | D11: Eolico | E11: =IFERROR(VLOOKUP(C11,DB_Impianti!C:E,3,0),"") -> BANCO ENERGIA | F11: =IFERROR(VLOOKUP(C11,DB_Impianti!C:F,4,0),"") -> Moncada Energy Group Srl | G11: =IFERROR(VLOOKUP(C11,DB_Impianti!C:G,5,0),"") -> PVI_S19MDEN_001 | H11: =IFERROR(VLOOKUP(C11,DB_Impianti!C:H,6,0),0) -> -1.86 | I11: Febbraio 2026 | J11: =IFERROR(SUMIFS(Fonte_Dati!E:E,Fonte_Dati!D:D,C11,Fonte_Dati!C:C,"Febbraio")/1000,0) -> 4130.1921 | K11: =IFERROR(SUMIFS(Fonte_Dati!F:F,Fonte_Dati!D:D,C11,Fonte_Dati!C:C,"Febbraio")/1000,0) -> 4130.1921 | L11: =IFERROR(SUMIFS(Fonte_Dati!G:G,Fonte_Dati!D:D,C11,Fonte_Dati!C:C,"Febbraio"),0) -> 427229.74 | M11: =IFERROR(SUMIFS(Fonte_Dati!H:H,Fonte_Dati!D:D,C11,Fonte_Dati!C:C,"Febbraio"),0) -> -826.03842 | N11: =IFERROR(SUMIFS(Fonte_Dati!I:I,Fonte_Dati!D:D,C11,Fonte_Dati!C:C,"Febbraio"),0) -> 426403.7 | O11: =IFERROR(N11/K11,0) -> 103.24065
B12: 2 | C12: Wind - Monte Durrà | D12: Eolico | E12: =IFERROR(VLOOKUP(C12,DB_Impianti!C:E,3,0),"") -> BANCO ENERGIA | F12: =IFERROR(VLOOKUP(C12,DB_Impianti!C:F,4,0),"") -> Moncada Energy Group Srl | G12: =IFERROR(VLOOKUP(C12,DB_Impianti!C:G,5,0),"") -> PVI_S19MDEN_001 | H12: =IFERROR(VLOOKUP(C12,DB_Impianti!C:H,6,0),0) -> -1.86 | I12: Marzo 2026 | J12: =IFERROR(SUMIFS(Fonte_Dati!E:E,Fonte_Dati!D:D,C12,Fonte_Dati!C:C,"Marzo")/1000,0) -> 0 | K12: =IFERROR(SUMIFS(Fonte_Dati!F:F,Fonte_Dati!D:D,C12,Fonte_Dati!C:C,"Marzo")/1000,0) -> 0 | L12: =IFERROR(SUMIFS(Fonte_Dati!G:G,Fonte_Dati!D:D,C12,Fonte_Dati!C:C,"Marzo"),0) -> 0 | M12: =IFERROR(SUMIFS(Fonte_Dati!H:H,Fonte_Dati!D:D,C12,Fonte_Dati!C:C,"Marzo"),0) -> 0 | N12: =IFERROR(SUMIFS(Fonte_Dati!I:I,Fonte_Dati!D:D,C12,Fonte_Dati!C:C,"Marzo"),0) -> 0 | O12: =IFERROR(N12/K12,0) -> 0
B13: 3 | C13: Wind - Monte Malvizzo | D13: Eolico | E13: =IFERROR(VLOOKUP(C13,DB_Impianti!C:E,3,0),"") -> DXT | F13: =IFERROR(VLOOKUP(C13,DB_Impianti!C:F,4,0),"") -> Moncada Energy Group Srl | G13: =IFERROR(VLOOKUP(C13,DB_Impianti!C:G,5,0),"") -> PVI_S19MMEN_001 | H13: =IFERROR(VLOOKUP(C13,DB_Impianti!C:H,6,0),0) -> -1.36 | I13: Gennaio 2026 | J13: =IFERROR(SUMIFS(Fonte_Dati!E:E,Fonte_Dati!D:D,C13,Fonte_Dati!C:C,"Gennaio")/1000,0) -> 1906.8542 | K13: =IFERROR(SUMIFS(Fonte_Dati!F:F,Fonte_Dati!D:D,C13,Fonte_Dati!C:C,"Gennaio")/1000,0) -> 1906.8542 | L13: =IFERROR(SUMIFS(Fonte_Dati!G:G,Fonte_Dati!D:D,C13,Fonte_Dati!C:C,"Gennaio"),0) -> 227341.49 | M13: =IFERROR(SUMIFS(Fonte_Dati!H:H,Fonte_Dati!D:D,C13,Fonte_Dati!C:C,"Gennaio"),0) -> -381.37083 | N13: =IFERROR(SUMIFS(Fonte_Dati!I:I,Fonte_Dati!D:D,C13,Fonte_Dati!C:C,"Gennaio"),0) -> 226960.12 | O13: =IFERROR(N13/K13,0) -> 119.02333
B14: 3 | C14: Wind - Monte Malvizzo | D14: Eolico | E14: =IFERROR(VLOOKUP(C14,DB_Impianti!C:E,3,0),"") -> DXT | F14: =IFERROR(VLOOKUP(C14,DB_Impianti!C:F,4,0),"") -> Moncada Energy Group Srl | G14: =IFERROR(VLOOKUP(C14,DB_Impianti!C:G,5,0),"") -> PVI_S19MMEN_001 | H14: =IFERROR(VLOOKUP(C14,DB_Impianti!C:H,6,0),0) -> -1.36 | I14: Febbraio 2026 | J14: =IFERROR(SUMIFS(Fonte_Dati!E:E,Fonte_Dati!D:D,C14,Fonte_Dati!C:C,"Febbraio")/1000,0) -> 2037.2792 | K14: =IFERROR(SUMIFS(Fonte_Dati!F:F,Fonte_Dati!D:D,C14,Fonte_Dati!C:C,"Febbraio")/1000,0) -> 2037.2792 | L14: =IFERROR(SUMIFS(Fonte_Dati!G:G,Fonte_Dati!D:D,C14,Fonte_Dati!C:C,"Febbraio"),0) -> 217599.32 | M14: =IFERROR(SUMIFS(Fonte_Dati!H:H,Fonte_Dati!D:D,C14,Fonte_Dati!C:C,"Febbraio"),0) -> -407.45583 | N14: =IFERROR(SUMIFS(Fonte_Dati!I:I,Fonte_Dati!D:D,C14,Fonte_Dati!C:C,"Febbraio"),0) -> 217191.86 | O14: =IFERROR(N14/K14,0) -> 106.60879
